<?xml version="1.0" ?>
<robot name="roller_conveyor_5ft">

    <!-- Base Frame -->
    <link name="base_link">
        <visual>
            <geometry>
                <box size="1.65 1.219 0.1"/>
            </geometry>
            <material name="gray">
                <color rgba="0.6 0.6 0.6 1.0"/>
            </material>
        </visual>
        <collision>
            <geometry>
                <box size="1.65 1.219 0.1"/>
            </geometry>
        </collision>
        <inertial>
            <mass value="20.0"/>
            <inertia ixx="0.2" iyy="0.2" izz="0.2"/>
        </inertial>
    </link>

    <!-- Left Guide Frame-->
    <link name="leftFrame">
        <visual>
            <geometry>
                <box size="1.65 0.05 0.5"/>
            </geometry>
            <material name="gray">
                <color rgba="0.6 0.6 0.6 1.0"/>
            </material>
        </visual>
        <collision>
            <geometry>
                <box size="1.65 0.05 0.5"/>
            </geometry>
        </collision>
        <inertial>
            <mass value="20.0"/>
            <inertia ixx="0.2" iyy="0.2" izz="0.2"/>
        </inertial>
    </link>
    <joint name="leftFrameJoint" type="fixed">
        <parent link="base_link"/>
        <child link="leftFrame"/>
        <origin xyz="0 -0.63 0.2" rpy="0 0 0"/>
        <axis xyz="0 0 1"/>
    </joint>

    <!-- Right Guide Frame-->
    <link name="rightFrame">
        <visual>
            <geometry>
                <box size="1.65 0.05 0.5"/>
            </geometry>
            <material name="gray">
                <color rgba="0.6 0.6 0.6 1.0"/>
            </material>
        </visual>
        <collision>
            <geometry>
                <box size="1.65 0.05 0.5"/>
            </geometry>
        </collision>
        <inertial>
            <mass value="20.0"/>
            <inertia ixx="0.2" iyy="0.2" izz="0.2"/>
        </inertial>
    </link>
    <joint name="rightFrameJoint" type="fixed">
        <parent link="base_link"/>
        <child link="rightFrame"/>
        <origin xyz="0 0.63 0.2" rpy="0 0 0"/>
        <axis xyz="0 0 1"/>
    </joint>


    <!-- Rollers -->
    <!-- 14 Rollers, Spacing = 1.524m / (14 - 1) ≈ 0.117m apart -->

    <!-- Define 14 Rollers -->
    <!-- Roller Diameter = 50.8mm (0.0508m), Length = 4ft (1.219m) -->
    
    <!-- Rollers List -->
    <!-- Each roller has a continuous joint allowing unlimited rotation -->
    
    <!-- Looping manually without macros -->

    <!-- 14 Rollers Definition -->
    <!-- Index i ∈ [0, 13], Position Y = -0.762 + i * 0.117m -->
    
    <!-- Roller Definition Loop -->
    <!-- Define 14 rollers manually -->

    <!-- Start Roller Definitions -->
    <!-- Roller 1 -->
    <link name="roller_1"><visual><geometry><cylinder radius="0.0254" length="1.219"/></geometry></visual>
        <collision>
            <geometry>
                <cylinder radius="0.0254" length="1.219"/>
            </geometry>
        </collision>
        <inertial>
            <mass value="2.0"/>
            <inertia ixx="0.02" iyy="0.02" izz="0.02"/>
        </inertial>
    </link>
    <joint name="roller_1_joint" type="continuous">
        <parent link="base_link"/>
        <child link="roller_1"/>
        <origin xyz="-0.762 0 0.15" rpy="1.570796 0 0"/>
        <limit lower="-180.0" upper="180.0" effort="0.0" velocity="10.0"/>
        <axis xyz="0 0 1"/>
    </joint>

    <!-- Roller 2 -->
    <link name="roller_2"><visual><geometry><cylinder radius="0.0254" length="1.219"/></geometry></visual>
        <collision>
            <geometry>
                <cylinder radius="0.0254" length="1.219"/>
            </geometry>
        </collision>
        <inertial>
            <mass value="2.0"/>
            <inertia ixx="0.02" iyy="0.02" izz="0.02"/>
        </inertial>
    </link>
    <joint name="roller_2_joint" type="continuous">
        <parent link="base_link"/>
        <child link="roller_2"/>
        <origin xyz="-0.645 0 0.15" rpy="1.570796 0 0"/>
        <axis xyz="0 0 1"/>
        <mimic joint="roller_1_joint" multiplier="1.0"/>
    </joint>

    <!-- Roller 3 -->
    <link name="roller_3"><visual><geometry><cylinder radius="0.0254" length="1.219"/></geometry></visual>
        <collision>
            <geometry>
                <cylinder radius="0.0254" length="1.219"/>
            </geometry>
        </collision>
        <inertial>
            <mass value="2.0"/>
            <inertia ixx="0.02" iyy="0.02" izz="0.02"/>
        </inertial>
    </link>
    <joint name="roller_3_joint" type="continuous">
        <parent link="base_link"/>
        <child link="roller_3"/>
        <origin xyz="-0.528 0 0.15" rpy="1.570796 0 0"/>
        <axis xyz="0 0 1"/>
        <mimic joint="roller_1_joint" multiplier="1.0"/>
    </joint>

    <!-- Roller 4 -->
    <link name="roller_4"><visual><geometry><cylinder radius="0.0254" length="1.219"/></geometry></visual>
        <collision>
            <geometry>
                <cylinder radius="0.0254" length="1.219"/>
            </geometry>
        </collision>
        <inertial>
            <mass value="2.0"/>
            <inertia ixx="0.02" iyy="0.02" izz="0.02"/>
        </inertial>
    </link>
    <joint name="roller_4_joint" type="continuous">
        <parent link="base_link"/>
        <child link="roller_4"/>
        <origin xyz="-0.411 0 0.15" rpy="1.570796 0 0"/>
        <axis xyz="0 0 1"/>
        <mimic joint="roller_1_joint" multiplier="1.0"/>
    </joint>

    <!-- Roller 5 -->
    <link name="roller_5"><visual><geometry><cylinder radius="0.0254" length="1.219"/></geometry></visual>
        <collision>
            <geometry>
                <cylinder radius="0.0254" length="1.219"/>
            </geometry>
        </collision>
        <inertial>
            <mass value="2.0"/>
            <inertia ixx="0.02" iyy="0.02" izz="0.02"/>
        </inertial>
    </link>
    <joint name="roller_5_joint" type="continuous">
        <parent link="base_link"/>
        <child link="roller_5"/>
        <origin xyz="-0.294 0 0.15" rpy="1.570796 0 0"/>
        <axis xyz="0 0 1"/>
        <mimic joint="roller_1_joint" multiplier="1.0"/>
    </joint>

    <!-- Roller 6 -->
    <link name="roller_6"><visual><geometry><cylinder radius="0.0254" length="1.219"/></geometry></visual>
        <collision>
            <geometry>
                <cylinder radius="0.0254" length="1.219"/>
            </geometry>
        </collision>
        <inertial>
            <mass value="2.0"/>
            <inertia ixx="0.02" iyy="0.02" izz="0.02"/>
        </inertial>
    </link>
    <joint name="roller_6_joint" type="continuous">
        <parent link="base_link"/>
        <child link="roller_6"/>
        <origin xyz="-0.177 0 0.15" rpy="1.570796 0 0"/>
        <axis xyz="0 0 1"/>
        <mimic joint="roller_1_joint" multiplier="1.0"/>
    </joint>

    <!-- Roller 7 -->
    <link name="roller_7"><visual><geometry><cylinder radius="0.0254" length="1.219"/></geometry></visual>
        <collision>
            <geometry>
                <cylinder radius="0.0254" length="1.219"/>
            </geometry>
        </collision>
        <inertial>
            <mass value="2.0"/>
            <inertia ixx="0.02" iyy="0.02" izz="0.02"/>
        </inertial>
    </link>
    <joint name="roller_7_joint" type="continuous">
        <parent link="base_link"/>
        <child link="roller_7"/>
        <origin xyz="-0.06 0 0.15" rpy="1.570796 0 0"/>
        <axis xyz="0 0 1"/>
        <mimic joint="roller_1_joint" multiplier="1.0"/>
    </joint>

    <!-- Roller 8 -->
    <link name="roller_8"><visual><geometry><cylinder radius="0.0254" length="1.219"/></geometry></visual>
        <collision>
            <geometry>
                <cylinder radius="0.0254" length="1.219"/>
            </geometry>
        </collision>
        <inertial>
            <mass value="2.0"/>
            <inertia ixx="0.02" iyy="0.02" izz="0.02"/>
        </inertial>
    </link>
    <joint name="roller_8_joint" type="continuous">
        <parent link="base_link"/>
        <child link="roller_8"/>
        <origin xyz="0.057 0 0.15" rpy="1.570796 0 0"/>
        <axis xyz="0 0 1"/>
        <mimic joint="roller_1_joint" multiplier="1.0"/>
    </joint>

    <!-- Roller 9 -->
    <link name="roller_9"><visual><geometry><cylinder radius="0.0254" length="1.219"/></geometry></visual>
        <collision>
            <geometry>
                <cylinder radius="0.0254" length="1.219"/>
            </geometry>
        </collision>
        <inertial>
            <mass value="2.0"/>
            <inertia ixx="0.02" iyy="0.02" izz="0.02"/>
        </inertial>
    </link>
    <joint name="roller_9_joint" type="continuous">
        <parent link="base_link"/>
        <child link="roller_9"/>
        <origin xyz="0.174 0 0.15" rpy="1.570796 0 0"/>
        <axis xyz="0 0 1"/>
        <mimic joint="roller_1_joint" multiplier="1.0"/>
    </joint>

    <!-- Roller 10 -->
    <link name="roller_10"><visual><geometry><cylinder radius="0.0254" length="1.219"/></geometry></visual>
        <collision>
            <geometry>
                <cylinder radius="0.0254" length="1.219"/>
            </geometry>
        </collision>
        <inertial>
            <mass value="2.0"/>
            <inertia ixx="0.02" iyy="0.02" izz="0.02"/>
        </inertial>
    </link>
    <joint name="roller_10_joint" type="continuous">
        <parent link="base_link"/>
        <child link="roller_10"/>
        <origin xyz="0.291 0 0.15" rpy="1.570796 0 0"/>
        <axis xyz="0 0 1"/>
        <mimic joint="roller_1_joint" multiplier="1.0"/>
    </joint>

    <!-- Roller 11 -->
    <link name="roller_11"><visual><geometry><cylinder radius="0.0254" length="1.219"/></geometry></visual>
        <collision>
            <geometry>
                <cylinder radius="0.0254" length="1.219"/>
            </geometry>
        </collision>
        <inertial>
            <mass value="2.0"/>
            <inertia ixx="0.02" iyy="0.02" izz="0.02"/>
        </inertial>
    </link>
    <joint name="roller_11_joint" type="continuous">
        <parent link="base_link"/>
        <child link="roller_11"/>
        <origin xyz="0.408 0 0.15" rpy="1.570796 0 0"/>
        <axis xyz="0 0 1"/>
        <mimic joint="roller_1_joint" multiplier="1.0"/>
    </joint>

    <!-- Roller 12 -->
    <link name="roller_12"><visual><geometry><cylinder radius="0.0254" length="1.219"/></geometry></visual>
        <collision>
            <geometry>
                <cylinder radius="0.0254" length="1.219"/>
            </geometry>
        </collision>
        <inertial>
            <mass value="2.0"/>
            <inertia ixx="0.02" iyy="0.02" izz="0.02"/>
        </inertial>
    </link>
    <joint name="roller_12_joint" type="continuous">
        <parent link="base_link"/>
        <child link="roller_12"/>
        <origin xyz="0.525 0 0.15" rpy="1.570796 0 0"/>
        <axis xyz="0 0 1"/>
        <mimic joint="roller_1_joint" multiplier="1.0"/>
    </joint>

    <!-- Roller 13 -->
    <link name="roller_13"><visual><geometry><cylinder radius="0.0254" length="1.219"/></geometry></visual>
        <collision>
            <geometry>
                <cylinder radius="0.0254" length="1.219"/>
            </geometry>
        </collision>
        <inertial>
            <mass value="2.0"/>
            <inertia ixx="0.02" iyy="0.02" izz="0.02"/>
        </inertial>
    </link>
    <joint name="roller_13_joint" type="continuous">
        <parent link="base_link"/>
        <child link="roller_13"/>
        <origin xyz="0.642 0 0.15" rpy="1.570796 0 0"/>
        <axis xyz="0 0 1"/>
        <mimic joint="roller_1_joint" multiplier="1.0"/>
    </joint>

    <!-- Roller 14 -->
    <link name="roller_14"><visual><geometry><cylinder radius="0.0254" length="1.219"/></geometry></visual>
        <collision>
            <geometry>
                <cylinder radius="0.0254" length="1.219"/>
            </geometry>
        </collision>
        <inertial>
            <mass value="2.0"/>
            <inertia ixx="0.02" iyy="0.02" izz="0.02"/>
        </inertial>
    </link>
    <joint name="roller_14_joint" type="continuous">
        <parent link="base_link"/>
        <child link="roller_14"/>
        <origin xyz="0.759 0 0.15" rpy="1.570796 0 0"/>
        <axis xyz="0 0 1"/>
        <mimic joint="roller_1_joint" multiplier="1.0"/>
    </joint>

</robot>
