<?xml version="1.0" ?>
<!-- =================================================================================== -->
<!-- |    This document was autogenerated by xacro from custom40ftStraight_v3.xacro    | -->
<!-- |    EDITING THIS FILE BY HAND IS NOT RECOMMENDED                                 | -->
<!-- =================================================================================== -->
<robot name="roller_conveyor_40ft">
  <link name="base_footprint"/>
  <joint name="base_link" type="fixed">
    <origin rpy="0 0 0" xyz="0 0 0"/>
    <parent link="base_footprint"/>
    <child link="base_link"/>
  </joint>
  <!-- Base Frame -->
  <link name="base_link">
    <visual>
      <origin rpy="0 0 0" xyz="-6.096 0 0"/>
      <geometry>
        <box size="12.192 1.219 2.0"/>
      </geometry>
      <material name="gray">
        <color rgba="0.6 0.6 0.6 1.0"/>
      </material>
    </visual>
    <collision>
      <origin rpy="0 0 0" xyz="-6.096 0 1.0"/>
      <geometry>
        <box size="12.192 1.219 2.0"/>
      </geometry>
    </collision>
    <inertial>
      <origin rpy="0 0 0" xyz="-6.096 0 1.0"/>
      <mass value="20.0"/>
      <inertia ixx="0.2" iyy="0.2" izz="0.2"/>
    </inertial>
  </link>
  <!-- Left Guide Frame-->
  <link name="leftFrame">
    <visual>
      <origin rpy="0 0 0" xyz="-6.096 0 0.0"/>
      <geometry>
        <box size="12.192 0.05 2.5"/>
      </geometry>
      <material name="gray">
        <color rgba="0.6 0.6 0.6 1.0"/>
      </material>
    </visual>
    <collision>
      <origin rpy="0 0 0" xyz="-6.096 0 0.0"/>
      <geometry>
        <box size="12.192 0.05 2.5"/>
      </geometry>
    </collision>
    <inertial>
      <origin rpy="0 0 0" xyz="-6.096 0 0.0"/>
      <mass value="20.0"/>
      <inertia ixx="0.2" iyy="0.2" izz="0.2"/>
    </inertial>
  </link>
  <joint name="leftFrameJoint" type="fixed">
    <parent link="base_link"/>
    <child link="leftFrame"/>
    <origin rpy="0 0 0" xyz="0 -0.63 0.2"/>
    <axis xyz="0 0 1"/>
  </joint>
  <!-- Right Guide Frame-->
  <link name="rightFrame">
    <visual>
      <origin rpy="0 0 0" xyz="-6.096 0 0"/>
      <geometry>
        <box size="12.192 0.05 2.5"/>
      </geometry>
      <material name="gray">
        <color rgba="0.6 0.6 0.6 1.0"/>
      </material>
    </visual>
    <collision>
      <origin rpy="0 0 0" xyz="-6.096 0 0"/>
      <geometry>
        <box size="12.192 0.05 2.5"/>
      </geometry>
    </collision>
    <inertial>
      <origin rpy="0 0 0" xyz="-6.096 0 0"/>
      <mass value="20.0"/>
      <inertia ixx="0.2" iyy="0.2" izz="0.2"/>
    </inertial>
  </link>
  <joint name="rightFrameJoint" type="fixed">
    <parent link="base_link"/>
    <child link="rightFrame"/>
    <origin rpy="0 0 0" xyz="0 0.63 0.2"/>
    <axis xyz="0 0 1"/>
  </joint>
  <!-- Start Roller Definitions -->
  <!-- In between rollers, starting from #1->#32 -->
  <!-- Roller 1 -->
  <link name="Roller_1">
    <visual>
      <geometry>
        <cylinder length="1.219" radius="0.025"/>
      </geometry>
    </visual>
    <visual>
      <geometry>
        <cylinder length="1.219" radius="0.025"/>
      </geometry>
      <material name="black">
        <color rgba="0.1 0.1 0.1 1.0"/>
      </material>
    </visual>
    <collision>
      <geometry>
        <cylinder length="1.219" radius="0.025"/>
      </geometry>
    </collision>
    <inertial>
      <mass value="2.0"/>
      <inertia ixx="0.02" iyy="0.02" izz="0.02"/>
    </inertial>
  </link>
  <joint name="Roller_1_1_joint" type="continuous">
    <parent link="base_link"/>
    <child link="Roller_1"/>
    <origin rpy="1.570796 0 0" xyz="-0.047625 0 1.15"/>
    <axis xyz="0 0 1"/>
    <dynamics damping="1.0" friction="0.0"/>
  </joint>
  <!-- Roller 17 -->
  <link name="Roller_17">
    <visual>
      <geometry>
        <cylinder length="1.219" radius="0.025"/>
      </geometry>
    </visual>
    <visual>
      <geometry>
        <cylinder length="1.219" radius="0.025"/>
      </geometry>
      <material name="black">
        <color rgba="0.1 0.1 0.1 1.0"/>
      </material>
    </visual>
    <collision>
      <geometry>
        <cylinder length="1.219" radius="0.025"/>
      </geometry>
    </collision>
    <inertial>
      <mass value="2.0"/>
      <inertia ixx="0.02" iyy="0.02" izz="0.02"/>
    </inertial>
  </link>
  <joint name="Roller_17_17_joint" type="continuous">
    <parent link="base_link"/>
    <child link="Roller_17"/>
    <origin rpy="1.570796 0 0" xyz="-1.571625 0 1.15"/>
    <axis xyz="0 0 1"/>
    <dynamics damping="1.0" friction="0.0"/>
  </joint>
  <!-- In between rollers, starting from #33->#64 -->
  <!-- Roller #33 -->
  <link name="Roller_33">
    <visual>
      <geometry>
        <cylinder length="1.219" radius="0.025"/>
      </geometry>
    </visual>
    <visual>
      <geometry>
        <cylinder length="1.219" radius="0.025"/>
      </geometry>
      <material name="black">
        <color rgba="0.1 0.1 0.1 1.0"/>
      </material>
    </visual>
    <collision>
      <geometry>
        <cylinder length="1.219" radius="0.025"/>
      </geometry>
    </collision>
    <inertial>
      <mass value="2.0"/>
      <inertia ixx="0.02" iyy="0.02" izz="0.02"/>
    </inertial>
  </link>
  <joint name="Roller_33_33_joint" type="continuous">
    <parent link="base_link"/>
    <child link="Roller_33"/>
    <origin rpy="1.570796 0 0" xyz="-3.095625 0 1.15"/>
    <axis xyz="0 0 1"/>
    <dynamics damping="1.0" friction="0.0"/>
  </joint>
  <!-- Roller 49 -->
  <link name="Roller_49">
    <visual>
      <geometry>
        <cylinder length="1.219" radius="0.025"/>
      </geometry>
    </visual>
    <visual>
      <geometry>
        <cylinder length="1.219" radius="0.025"/>
      </geometry>
      <material name="black">
        <color rgba="0.1 0.1 0.1 1.0"/>
      </material>
    </visual>
    <collision>
      <geometry>
        <cylinder length="1.219" radius="0.025"/>
      </geometry>
    </collision>
    <inertial>
      <mass value="2.0"/>
      <inertia ixx="0.02" iyy="0.02" izz="0.02"/>
    </inertial>
  </link>
  <joint name="Roller_49_49_joint" type="continuous">
    <parent link="base_link"/>
    <child link="Roller_49"/>
    <origin rpy="1.570796 0 0" xyz="-4.619625 0 1.15"/>
    <axis xyz="0 0 1"/>
    <dynamics damping="1.0" friction="0.0"/>
  </joint>
  <!-- In between rollders, starting from #65->#80 -->
  <!-- Roller #65 -->
  <link name="Roller_65">
    <visual>
      <geometry>
        <cylinder length="1.219" radius="0.025"/>
      </geometry>
    </visual>
    <visual>
      <geometry>
        <cylinder length="1.219" radius="0.025"/>
      </geometry>
      <material name="black">
        <color rgba="0.1 0.1 0.1 1.0"/>
      </material>
    </visual>
    <collision>
      <geometry>
        <cylinder length="1.219" radius="0.025"/>
      </geometry>
    </collision>
    <inertial>
      <mass value="2.0"/>
      <inertia ixx="0.02" iyy="0.02" izz="0.02"/>
    </inertial>
  </link>
  <joint name="Roller_65_65_joint" type="continuous">
    <parent link="base_link"/>
    <child link="Roller_65"/>
    <origin rpy="1.570796 0 0" xyz="-6.143625 0 1.15"/>
    <axis xyz="0 0 1"/>
    <dynamics damping="1.0" friction="0.0"/>
  </joint>
  <!-- Roller 81 -->
  <link name="Roller_81">
    <visual>
      <geometry>
        <cylinder length="1.219" radius="0.025"/>
      </geometry>
    </visual>
    <visual>
      <geometry>
        <cylinder length="1.219" radius="0.025"/>
      </geometry>
      <material name="black">
        <color rgba="0.1 0.1 0.1 1.0"/>
      </material>
    </visual>
    <collision>
      <geometry>
        <cylinder length="1.219" radius="0.025"/>
      </geometry>
    </collision>
    <inertial>
      <mass value="2.0"/>
      <inertia ixx="0.02" iyy="0.02" izz="0.02"/>
    </inertial>
  </link>
  <joint name="Roller_81_81_joint" type="continuous">
    <parent link="base_link"/>
    <child link="Roller_81"/>
    <origin rpy="1.570796 0 0" xyz="-7.667625 0 1.15"/>
    <axis xyz="0 0 1"/>
    <dynamics damping="1.0" friction="0.0"/>
  </joint>
  <!-- In between rollders, starting from #97->#112 -->
  <!-- Roller #97 -->
  <link name="Roller_97">
    <visual>
      <geometry>
        <cylinder length="1.219" radius="0.025"/>
      </geometry>
    </visual>
    <visual>
      <geometry>
        <cylinder length="1.219" radius="0.025"/>
      </geometry>
      <material name="black">
        <color rgba="0.1 0.1 0.1 1.0"/>
      </material>
    </visual>
    <collision>
      <geometry>
        <cylinder length="1.219" radius="0.025"/>
      </geometry>
    </collision>
    <inertial>
      <mass value="2.0"/>
      <inertia ixx="0.02" iyy="0.02" izz="0.02"/>
    </inertial>
  </link>
  <joint name="Roller_97_97_joint" type="continuous">
    <parent link="base_link"/>
    <child link="Roller_97"/>
    <origin rpy="1.570796 0 0" xyz="-9.191625 0 1.15"/>
    <axis xyz="0 0 1"/>
    <dynamics damping="1.0" friction="0.0"/>
  </joint>
  <!-- Roller 113 -->
  <link name="Roller_113">
    <visual>
      <geometry>
        <cylinder length="1.219" radius="0.025"/>
      </geometry>
    </visual>
    <visual>
      <geometry>
        <cylinder length="1.219" radius="0.025"/>
      </geometry>
      <material name="black">
        <color rgba="0.1 0.1 0.1 1.0"/>
      </material>
    </visual>
    <collision>
      <geometry>
        <cylinder length="1.219" radius="0.025"/>
      </geometry>
    </collision>
    <inertial>
      <mass value="2.0"/>
      <inertia ixx="0.02" iyy="0.02" izz="0.02"/>
    </inertial>
  </link>
  <joint name="Roller_113_113_joint" type="continuous">
    <parent link="base_link"/>
    <child link="Roller_113"/>
    <origin rpy="1.570796 0 0" xyz="-10.715625 0 1.15"/>
    <axis xyz="0 0 1"/>
    <dynamics damping="1.0" friction="0.0"/>
  </joint>
  <link name="Roller_2">
    <visual>
      <geometry>
        <cylinder length="1.219" radius="0.025"/>
      </geometry>
      <material name="black">
        <color rgba="0.1 0.1 0.1 1.0"/>
      </material>
    </visual>
    <collision>
      <geometry>
        <cylinder length="1.219" radius="0.025"/>
      </geometry>
    </collision>
    <inertial>
      <mass value="2.0"/>
      <inertia ixx="0.02" iyy="0.02" izz="0.02"/>
    </inertial>
  </link>
  <joint name="Roller_1_2_joint" type="continuous">
    <parent link="base_link"/>
    <child link="Roller_2"/>
    <origin rpy="1.5707963 0 0" xyz="-0.142875 0 1.15"/>
    <axis xyz="0 0 1"/>
    <dynamics damping="1.0" friction="0.0"/>
  </joint>
  <link name="Roller_3">
    <visual>
      <geometry>
        <cylinder length="1.219" radius="0.025"/>
      </geometry>
      <material name="black">
        <color rgba="0.1 0.1 0.1 1.0"/>
      </material>
    </visual>
    <collision>
      <geometry>
        <cylinder length="1.219" radius="0.025"/>
      </geometry>
    </collision>
    <inertial>
      <mass value="2.0"/>
      <inertia ixx="0.02" iyy="0.02" izz="0.02"/>
    </inertial>
  </link>
  <joint name="Roller_1_3_joint" type="continuous">
    <parent link="base_link"/>
    <child link="Roller_3"/>
    <origin rpy="1.5707963 0 0" xyz="-0.238125 0 1.15"/>
    <axis xyz="0 0 1"/>
    <dynamics damping="1.0" friction="0.0"/>
  </joint>
  <link name="Roller_4">
    <visual>
      <geometry>
        <cylinder length="1.219" radius="0.025"/>
      </geometry>
      <material name="black">
        <color rgba="0.1 0.1 0.1 1.0"/>
      </material>
    </visual>
    <collision>
      <geometry>
        <cylinder length="1.219" radius="0.025"/>
      </geometry>
    </collision>
    <inertial>
      <mass value="2.0"/>
      <inertia ixx="0.02" iyy="0.02" izz="0.02"/>
    </inertial>
  </link>
  <joint name="Roller_1_4_joint" type="continuous">
    <parent link="base_link"/>
    <child link="Roller_4"/>
    <origin rpy="1.5707963 0 0" xyz="-0.333375 0 1.15"/>
    <axis xyz="0 0 1"/>
    <dynamics damping="1.0" friction="0.0"/>
  </joint>
  <link name="Roller_5">
    <visual>
      <geometry>
        <cylinder length="1.219" radius="0.025"/>
      </geometry>
      <material name="black">
        <color rgba="0.1 0.1 0.1 1.0"/>
      </material>
    </visual>
    <collision>
      <geometry>
        <cylinder length="1.219" radius="0.025"/>
      </geometry>
    </collision>
    <inertial>
      <mass value="2.0"/>
      <inertia ixx="0.02" iyy="0.02" izz="0.02"/>
    </inertial>
  </link>
  <joint name="Roller_1_5_joint" type="continuous">
    <parent link="base_link"/>
    <child link="Roller_5"/>
    <origin rpy="1.5707963 0 0" xyz="-0.42862500000000003 0 1.15"/>
    <axis xyz="0 0 1"/>
    <dynamics damping="1.0" friction="0.0"/>
  </joint>
  <link name="Roller_6">
    <visual>
      <geometry>
        <cylinder length="1.219" radius="0.025"/>
      </geometry>
      <material name="black">
        <color rgba="0.1 0.1 0.1 1.0"/>
      </material>
    </visual>
    <collision>
      <geometry>
        <cylinder length="1.219" radius="0.025"/>
      </geometry>
    </collision>
    <inertial>
      <mass value="2.0"/>
      <inertia ixx="0.02" iyy="0.02" izz="0.02"/>
    </inertial>
  </link>
  <joint name="Roller_1_6_joint" type="continuous">
    <parent link="base_link"/>
    <child link="Roller_6"/>
    <origin rpy="1.5707963 0 0" xyz="-0.523875 0 1.15"/>
    <axis xyz="0 0 1"/>
    <dynamics damping="1.0" friction="0.0"/>
  </joint>
  <link name="Roller_7">
    <visual>
      <geometry>
        <cylinder length="1.219" radius="0.025"/>
      </geometry>
      <material name="black">
        <color rgba="0.1 0.1 0.1 1.0"/>
      </material>
    </visual>
    <collision>
      <geometry>
        <cylinder length="1.219" radius="0.025"/>
      </geometry>
    </collision>
    <inertial>
      <mass value="2.0"/>
      <inertia ixx="0.02" iyy="0.02" izz="0.02"/>
    </inertial>
  </link>
  <joint name="Roller_1_7_joint" type="continuous">
    <parent link="base_link"/>
    <child link="Roller_7"/>
    <origin rpy="1.5707963 0 0" xyz="-0.619125 0 1.15"/>
    <axis xyz="0 0 1"/>
    <dynamics damping="1.0" friction="0.0"/>
  </joint>
  <link name="Roller_8">
    <visual>
      <geometry>
        <cylinder length="1.219" radius="0.025"/>
      </geometry>
      <material name="black">
        <color rgba="0.1 0.1 0.1 1.0"/>
      </material>
    </visual>
    <collision>
      <geometry>
        <cylinder length="1.219" radius="0.025"/>
      </geometry>
    </collision>
    <inertial>
      <mass value="2.0"/>
      <inertia ixx="0.02" iyy="0.02" izz="0.02"/>
    </inertial>
  </link>
  <joint name="Roller_1_8_joint" type="continuous">
    <parent link="base_link"/>
    <child link="Roller_8"/>
    <origin rpy="1.5707963 0 0" xyz="-0.714375 0 1.15"/>
    <axis xyz="0 0 1"/>
    <dynamics damping="1.0" friction="0.0"/>
  </joint>
  <link name="Roller_9">
    <visual>
      <geometry>
        <cylinder length="1.219" radius="0.025"/>
      </geometry>
      <material name="black">
        <color rgba="0.1 0.1 0.1 1.0"/>
      </material>
    </visual>
    <collision>
      <geometry>
        <cylinder length="1.219" radius="0.025"/>
      </geometry>
    </collision>
    <inertial>
      <mass value="2.0"/>
      <inertia ixx="0.02" iyy="0.02" izz="0.02"/>
    </inertial>
  </link>
  <joint name="Roller_1_9_joint" type="continuous">
    <parent link="base_link"/>
    <child link="Roller_9"/>
    <origin rpy="1.5707963 0 0" xyz="-0.809625 0 1.15"/>
    <axis xyz="0 0 1"/>
    <dynamics damping="1.0" friction="0.0"/>
  </joint>
  <link name="Roller_10">
    <visual>
      <geometry>
        <cylinder length="1.219" radius="0.025"/>
      </geometry>
      <material name="black">
        <color rgba="0.1 0.1 0.1 1.0"/>
      </material>
    </visual>
    <collision>
      <geometry>
        <cylinder length="1.219" radius="0.025"/>
      </geometry>
    </collision>
    <inertial>
      <mass value="2.0"/>
      <inertia ixx="0.02" iyy="0.02" izz="0.02"/>
    </inertial>
  </link>
  <joint name="Roller_1_10_joint" type="continuous">
    <parent link="base_link"/>
    <child link="Roller_10"/>
    <origin rpy="1.5707963 0 0" xyz="-0.9048750000000001 0 1.15"/>
    <axis xyz="0 0 1"/>
    <dynamics damping="1.0" friction="0.0"/>
  </joint>
  <link name="Roller_11">
    <visual>
      <geometry>
        <cylinder length="1.219" radius="0.025"/>
      </geometry>
      <material name="black">
        <color rgba="0.1 0.1 0.1 1.0"/>
      </material>
    </visual>
    <collision>
      <geometry>
        <cylinder length="1.219" radius="0.025"/>
      </geometry>
    </collision>
    <inertial>
      <mass value="2.0"/>
      <inertia ixx="0.02" iyy="0.02" izz="0.02"/>
    </inertial>
  </link>
  <joint name="Roller_1_11_joint" type="continuous">
    <parent link="base_link"/>
    <child link="Roller_11"/>
    <origin rpy="1.5707963 0 0" xyz="-1.000125 0 1.15"/>
    <axis xyz="0 0 1"/>
    <dynamics damping="1.0" friction="0.0"/>
  </joint>
  <link name="Roller_12">
    <visual>
      <geometry>
        <cylinder length="1.219" radius="0.025"/>
      </geometry>
      <material name="black">
        <color rgba="0.1 0.1 0.1 1.0"/>
      </material>
    </visual>
    <collision>
      <geometry>
        <cylinder length="1.219" radius="0.025"/>
      </geometry>
    </collision>
    <inertial>
      <mass value="2.0"/>
      <inertia ixx="0.02" iyy="0.02" izz="0.02"/>
    </inertial>
  </link>
  <joint name="Roller_1_12_joint" type="continuous">
    <parent link="base_link"/>
    <child link="Roller_12"/>
    <origin rpy="1.5707963 0 0" xyz="-1.095375 0 1.15"/>
    <axis xyz="0 0 1"/>
    <dynamics damping="1.0" friction="0.0"/>
  </joint>
  <link name="Roller_13">
    <visual>
      <geometry>
        <cylinder length="1.219" radius="0.025"/>
      </geometry>
      <material name="black">
        <color rgba="0.1 0.1 0.1 1.0"/>
      </material>
    </visual>
    <collision>
      <geometry>
        <cylinder length="1.219" radius="0.025"/>
      </geometry>
    </collision>
    <inertial>
      <mass value="2.0"/>
      <inertia ixx="0.02" iyy="0.02" izz="0.02"/>
    </inertial>
  </link>
  <joint name="Roller_1_13_joint" type="continuous">
    <parent link="base_link"/>
    <child link="Roller_13"/>
    <origin rpy="1.5707963 0 0" xyz="-1.190625 0 1.15"/>
    <axis xyz="0 0 1"/>
    <dynamics damping="1.0" friction="0.0"/>
  </joint>
  <link name="Roller_14">
    <visual>
      <geometry>
        <cylinder length="1.219" radius="0.025"/>
      </geometry>
      <material name="black">
        <color rgba="0.1 0.1 0.1 1.0"/>
      </material>
    </visual>
    <collision>
      <geometry>
        <cylinder length="1.219" radius="0.025"/>
      </geometry>
    </collision>
    <inertial>
      <mass value="2.0"/>
      <inertia ixx="0.02" iyy="0.02" izz="0.02"/>
    </inertial>
  </link>
  <joint name="Roller_1_14_joint" type="continuous">
    <parent link="base_link"/>
    <child link="Roller_14"/>
    <origin rpy="1.5707963 0 0" xyz="-1.285875 0 1.15"/>
    <axis xyz="0 0 1"/>
    <dynamics damping="1.0" friction="0.0"/>
  </joint>
  <link name="Roller_15">
    <visual>
      <geometry>
        <cylinder length="1.219" radius="0.025"/>
      </geometry>
      <material name="black">
        <color rgba="0.1 0.1 0.1 1.0"/>
      </material>
    </visual>
    <collision>
      <geometry>
        <cylinder length="1.219" radius="0.025"/>
      </geometry>
    </collision>
    <inertial>
      <mass value="2.0"/>
      <inertia ixx="0.02" iyy="0.02" izz="0.02"/>
    </inertial>
  </link>
  <joint name="Roller_1_15_joint" type="continuous">
    <parent link="base_link"/>
    <child link="Roller_15"/>
    <origin rpy="1.5707963 0 0" xyz="-1.381125 0 1.15"/>
    <axis xyz="0 0 1"/>
    <dynamics damping="1.0" friction="0.0"/>
  </joint>
  <link name="Roller_16">
    <visual>
      <geometry>
        <cylinder length="1.219" radius="0.025"/>
      </geometry>
      <material name="black">
        <color rgba="0.1 0.1 0.1 1.0"/>
      </material>
    </visual>
    <collision>
      <geometry>
        <cylinder length="1.219" radius="0.025"/>
      </geometry>
    </collision>
    <inertial>
      <mass value="2.0"/>
      <inertia ixx="0.02" iyy="0.02" izz="0.02"/>
    </inertial>
  </link>
  <joint name="Roller_1_16_joint" type="continuous">
    <parent link="base_link"/>
    <child link="Roller_16"/>
    <origin rpy="1.5707963 0 0" xyz="-1.476375 0 1.15"/>
    <axis xyz="0 0 1"/>
    <dynamics damping="1.0" friction="0.0"/>
  </joint>
  <link name="Roller_18">
    <visual>
      <geometry>
        <cylinder length="1.219" radius="0.025"/>
      </geometry>
      <material name="black">
        <color rgba="0.1 0.1 0.1 1.0"/>
      </material>
    </visual>
    <collision>
      <geometry>
        <cylinder length="1.219" radius="0.025"/>
      </geometry>
    </collision>
    <inertial>
      <mass value="2.0"/>
      <inertia ixx="0.02" iyy="0.02" izz="0.02"/>
    </inertial>
  </link>
  <joint name="Roller_17_18_joint" type="continuous">
    <parent link="base_link"/>
    <child link="Roller_18"/>
    <origin rpy="1.5707963 0 0" xyz="-1.666875 0 1.15"/>
    <axis xyz="0 0 1"/>
    <dynamics damping="1.0" friction="0.0"/>
  </joint>
  <link name="Roller_19">
    <visual>
      <geometry>
        <cylinder length="1.219" radius="0.025"/>
      </geometry>
      <material name="black">
        <color rgba="0.1 0.1 0.1 1.0"/>
      </material>
    </visual>
    <collision>
      <geometry>
        <cylinder length="1.219" radius="0.025"/>
      </geometry>
    </collision>
    <inertial>
      <mass value="2.0"/>
      <inertia ixx="0.02" iyy="0.02" izz="0.02"/>
    </inertial>
  </link>
  <joint name="Roller_17_19_joint" type="continuous">
    <parent link="base_link"/>
    <child link="Roller_19"/>
    <origin rpy="1.5707963 0 0" xyz="-1.7621250000000002 0 1.15"/>
    <axis xyz="0 0 1"/>
    <dynamics damping="1.0" friction="0.0"/>
  </joint>
  <link name="Roller_20">
    <visual>
      <geometry>
        <cylinder length="1.219" radius="0.025"/>
      </geometry>
      <material name="black">
        <color rgba="0.1 0.1 0.1 1.0"/>
      </material>
    </visual>
    <collision>
      <geometry>
        <cylinder length="1.219" radius="0.025"/>
      </geometry>
    </collision>
    <inertial>
      <mass value="2.0"/>
      <inertia ixx="0.02" iyy="0.02" izz="0.02"/>
    </inertial>
  </link>
  <joint name="Roller_17_20_joint" type="continuous">
    <parent link="base_link"/>
    <child link="Roller_20"/>
    <origin rpy="1.5707963 0 0" xyz="-1.857375 0 1.15"/>
    <axis xyz="0 0 1"/>
    <dynamics damping="1.0" friction="0.0"/>
  </joint>
  <link name="Roller_21">
    <visual>
      <geometry>
        <cylinder length="1.219" radius="0.025"/>
      </geometry>
      <material name="black">
        <color rgba="0.1 0.1 0.1 1.0"/>
      </material>
    </visual>
    <collision>
      <geometry>
        <cylinder length="1.219" radius="0.025"/>
      </geometry>
    </collision>
    <inertial>
      <mass value="2.0"/>
      <inertia ixx="0.02" iyy="0.02" izz="0.02"/>
    </inertial>
  </link>
  <joint name="Roller_17_21_joint" type="continuous">
    <parent link="base_link"/>
    <child link="Roller_21"/>
    <origin rpy="1.5707963 0 0" xyz="-1.952625 0 1.15"/>
    <axis xyz="0 0 1"/>
    <dynamics damping="1.0" friction="0.0"/>
  </joint>
  <link name="Roller_22">
    <visual>
      <geometry>
        <cylinder length="1.219" radius="0.025"/>
      </geometry>
      <material name="black">
        <color rgba="0.1 0.1 0.1 1.0"/>
      </material>
    </visual>
    <collision>
      <geometry>
        <cylinder length="1.219" radius="0.025"/>
      </geometry>
    </collision>
    <inertial>
      <mass value="2.0"/>
      <inertia ixx="0.02" iyy="0.02" izz="0.02"/>
    </inertial>
  </link>
  <joint name="Roller_17_22_joint" type="continuous">
    <parent link="base_link"/>
    <child link="Roller_22"/>
    <origin rpy="1.5707963 0 0" xyz="-2.047875 0 1.15"/>
    <axis xyz="0 0 1"/>
    <dynamics damping="1.0" friction="0.0"/>
  </joint>
  <link name="Roller_23">
    <visual>
      <geometry>
        <cylinder length="1.219" radius="0.025"/>
      </geometry>
      <material name="black">
        <color rgba="0.1 0.1 0.1 1.0"/>
      </material>
    </visual>
    <collision>
      <geometry>
        <cylinder length="1.219" radius="0.025"/>
      </geometry>
    </collision>
    <inertial>
      <mass value="2.0"/>
      <inertia ixx="0.02" iyy="0.02" izz="0.02"/>
    </inertial>
  </link>
  <joint name="Roller_17_23_joint" type="continuous">
    <parent link="base_link"/>
    <child link="Roller_23"/>
    <origin rpy="1.5707963 0 0" xyz="-2.143125 0 1.15"/>
    <axis xyz="0 0 1"/>
    <dynamics damping="1.0" friction="0.0"/>
  </joint>
  <link name="Roller_24">
    <visual>
      <geometry>
        <cylinder length="1.219" radius="0.025"/>
      </geometry>
      <material name="black">
        <color rgba="0.1 0.1 0.1 1.0"/>
      </material>
    </visual>
    <collision>
      <geometry>
        <cylinder length="1.219" radius="0.025"/>
      </geometry>
    </collision>
    <inertial>
      <mass value="2.0"/>
      <inertia ixx="0.02" iyy="0.02" izz="0.02"/>
    </inertial>
  </link>
  <joint name="Roller_17_24_joint" type="continuous">
    <parent link="base_link"/>
    <child link="Roller_24"/>
    <origin rpy="1.5707963 0 0" xyz="-2.238375 0 1.15"/>
    <axis xyz="0 0 1"/>
    <dynamics damping="1.0" friction="0.0"/>
  </joint>
  <link name="Roller_25">
    <visual>
      <geometry>
        <cylinder length="1.219" radius="0.025"/>
      </geometry>
      <material name="black">
        <color rgba="0.1 0.1 0.1 1.0"/>
      </material>
    </visual>
    <collision>
      <geometry>
        <cylinder length="1.219" radius="0.025"/>
      </geometry>
    </collision>
    <inertial>
      <mass value="2.0"/>
      <inertia ixx="0.02" iyy="0.02" izz="0.02"/>
    </inertial>
  </link>
  <joint name="Roller_17_25_joint" type="continuous">
    <parent link="base_link"/>
    <child link="Roller_25"/>
    <origin rpy="1.5707963 0 0" xyz="-2.333625 0 1.15"/>
    <axis xyz="0 0 1"/>
    <dynamics damping="1.0" friction="0.0"/>
  </joint>
  <link name="Roller_26">
    <visual>
      <geometry>
        <cylinder length="1.219" radius="0.025"/>
      </geometry>
      <material name="black">
        <color rgba="0.1 0.1 0.1 1.0"/>
      </material>
    </visual>
    <collision>
      <geometry>
        <cylinder length="1.219" radius="0.025"/>
      </geometry>
    </collision>
    <inertial>
      <mass value="2.0"/>
      <inertia ixx="0.02" iyy="0.02" izz="0.02"/>
    </inertial>
  </link>
  <joint name="Roller_17_26_joint" type="continuous">
    <parent link="base_link"/>
    <child link="Roller_26"/>
    <origin rpy="1.5707963 0 0" xyz="-2.428875 0 1.15"/>
    <axis xyz="0 0 1"/>
    <dynamics damping="1.0" friction="0.0"/>
  </joint>
  <link name="Roller_27">
    <visual>
      <geometry>
        <cylinder length="1.219" radius="0.025"/>
      </geometry>
      <material name="black">
        <color rgba="0.1 0.1 0.1 1.0"/>
      </material>
    </visual>
    <collision>
      <geometry>
        <cylinder length="1.219" radius="0.025"/>
      </geometry>
    </collision>
    <inertial>
      <mass value="2.0"/>
      <inertia ixx="0.02" iyy="0.02" izz="0.02"/>
    </inertial>
  </link>
  <joint name="Roller_17_27_joint" type="continuous">
    <parent link="base_link"/>
    <child link="Roller_27"/>
    <origin rpy="1.5707963 0 0" xyz="-2.524125 0 1.15"/>
    <axis xyz="0 0 1"/>
    <dynamics damping="1.0" friction="0.0"/>
  </joint>
  <link name="Roller_28">
    <visual>
      <geometry>
        <cylinder length="1.219" radius="0.025"/>
      </geometry>
      <material name="black">
        <color rgba="0.1 0.1 0.1 1.0"/>
      </material>
    </visual>
    <collision>
      <geometry>
        <cylinder length="1.219" radius="0.025"/>
      </geometry>
    </collision>
    <inertial>
      <mass value="2.0"/>
      <inertia ixx="0.02" iyy="0.02" izz="0.02"/>
    </inertial>
  </link>
  <joint name="Roller_17_28_joint" type="continuous">
    <parent link="base_link"/>
    <child link="Roller_28"/>
    <origin rpy="1.5707963 0 0" xyz="-2.6193750000000002 0 1.15"/>
    <axis xyz="0 0 1"/>
    <dynamics damping="1.0" friction="0.0"/>
  </joint>
  <link name="Roller_29">
    <visual>
      <geometry>
        <cylinder length="1.219" radius="0.025"/>
      </geometry>
      <material name="black">
        <color rgba="0.1 0.1 0.1 1.0"/>
      </material>
    </visual>
    <collision>
      <geometry>
        <cylinder length="1.219" radius="0.025"/>
      </geometry>
    </collision>
    <inertial>
      <mass value="2.0"/>
      <inertia ixx="0.02" iyy="0.02" izz="0.02"/>
    </inertial>
  </link>
  <joint name="Roller_17_29_joint" type="continuous">
    <parent link="base_link"/>
    <child link="Roller_29"/>
    <origin rpy="1.5707963 0 0" xyz="-2.714625 0 1.15"/>
    <axis xyz="0 0 1"/>
    <dynamics damping="1.0" friction="0.0"/>
  </joint>
  <link name="Roller_30">
    <visual>
      <geometry>
        <cylinder length="1.219" radius="0.025"/>
      </geometry>
      <material name="black">
        <color rgba="0.1 0.1 0.1 1.0"/>
      </material>
    </visual>
    <collision>
      <geometry>
        <cylinder length="1.219" radius="0.025"/>
      </geometry>
    </collision>
    <inertial>
      <mass value="2.0"/>
      <inertia ixx="0.02" iyy="0.02" izz="0.02"/>
    </inertial>
  </link>
  <joint name="Roller_17_30_joint" type="continuous">
    <parent link="base_link"/>
    <child link="Roller_30"/>
    <origin rpy="1.5707963 0 0" xyz="-2.809875 0 1.15"/>
    <axis xyz="0 0 1"/>
    <dynamics damping="1.0" friction="0.0"/>
  </joint>
  <link name="Roller_31">
    <visual>
      <geometry>
        <cylinder length="1.219" radius="0.025"/>
      </geometry>
      <material name="black">
        <color rgba="0.1 0.1 0.1 1.0"/>
      </material>
    </visual>
    <collision>
      <geometry>
        <cylinder length="1.219" radius="0.025"/>
      </geometry>
    </collision>
    <inertial>
      <mass value="2.0"/>
      <inertia ixx="0.02" iyy="0.02" izz="0.02"/>
    </inertial>
  </link>
  <joint name="Roller_17_31_joint" type="continuous">
    <parent link="base_link"/>
    <child link="Roller_31"/>
    <origin rpy="1.5707963 0 0" xyz="-2.905125 0 1.15"/>
    <axis xyz="0 0 1"/>
    <dynamics damping="1.0" friction="0.0"/>
  </joint>
  <link name="Roller_32">
    <visual>
      <geometry>
        <cylinder length="1.219" radius="0.025"/>
      </geometry>
      <material name="black">
        <color rgba="0.1 0.1 0.1 1.0"/>
      </material>
    </visual>
    <collision>
      <geometry>
        <cylinder length="1.219" radius="0.025"/>
      </geometry>
    </collision>
    <inertial>
      <mass value="2.0"/>
      <inertia ixx="0.02" iyy="0.02" izz="0.02"/>
    </inertial>
  </link>
  <joint name="Roller_17_32_joint" type="continuous">
    <parent link="base_link"/>
    <child link="Roller_32"/>
    <origin rpy="1.5707963 0 0" xyz="-3.000375 0 1.15"/>
    <axis xyz="0 0 1"/>
    <dynamics damping="1.0" friction="0.0"/>
  </joint>
  <link name="Roller_34">
    <visual>
      <geometry>
        <cylinder length="1.219" radius="0.025"/>
      </geometry>
      <material name="black">
        <color rgba="0.1 0.1 0.1 1.0"/>
      </material>
    </visual>
    <collision>
      <geometry>
        <cylinder length="1.219" radius="0.025"/>
      </geometry>
    </collision>
    <inertial>
      <mass value="2.0"/>
      <inertia ixx="0.02" iyy="0.02" izz="0.02"/>
    </inertial>
  </link>
  <joint name="Roller_33_34_joint" type="continuous">
    <parent link="base_link"/>
    <child link="Roller_34"/>
    <origin rpy="1.5707963 0 0" xyz="-3.190875 0 1.15"/>
    <axis xyz="0 0 1"/>
    <dynamics damping="1.0" friction="0.0"/>
  </joint>
  <link name="Roller_35">
    <visual>
      <geometry>
        <cylinder length="1.219" radius="0.025"/>
      </geometry>
      <material name="black">
        <color rgba="0.1 0.1 0.1 1.0"/>
      </material>
    </visual>
    <collision>
      <geometry>
        <cylinder length="1.219" radius="0.025"/>
      </geometry>
    </collision>
    <inertial>
      <mass value="2.0"/>
      <inertia ixx="0.02" iyy="0.02" izz="0.02"/>
    </inertial>
  </link>
  <joint name="Roller_33_35_joint" type="continuous">
    <parent link="base_link"/>
    <child link="Roller_35"/>
    <origin rpy="1.5707963 0 0" xyz="-3.286125 0 1.15"/>
    <axis xyz="0 0 1"/>
    <dynamics damping="1.0" friction="0.0"/>
  </joint>
  <link name="Roller_36">
    <visual>
      <geometry>
        <cylinder length="1.219" radius="0.025"/>
      </geometry>
      <material name="black">
        <color rgba="0.1 0.1 0.1 1.0"/>
      </material>
    </visual>
    <collision>
      <geometry>
        <cylinder length="1.219" radius="0.025"/>
      </geometry>
    </collision>
    <inertial>
      <mass value="2.0"/>
      <inertia ixx="0.02" iyy="0.02" izz="0.02"/>
    </inertial>
  </link>
  <joint name="Roller_33_36_joint" type="continuous">
    <parent link="base_link"/>
    <child link="Roller_36"/>
    <origin rpy="1.5707963 0 0" xyz="-3.3813750000000002 0 1.15"/>
    <axis xyz="0 0 1"/>
    <dynamics damping="1.0" friction="0.0"/>
  </joint>
  <link name="Roller_37">
    <visual>
      <geometry>
        <cylinder length="1.219" radius="0.025"/>
      </geometry>
      <material name="black">
        <color rgba="0.1 0.1 0.1 1.0"/>
      </material>
    </visual>
    <collision>
      <geometry>
        <cylinder length="1.219" radius="0.025"/>
      </geometry>
    </collision>
    <inertial>
      <mass value="2.0"/>
      <inertia ixx="0.02" iyy="0.02" izz="0.02"/>
    </inertial>
  </link>
  <joint name="Roller_33_37_joint" type="continuous">
    <parent link="base_link"/>
    <child link="Roller_37"/>
    <origin rpy="1.5707963 0 0" xyz="-3.4766250000000003 0 1.15"/>
    <axis xyz="0 0 1"/>
    <dynamics damping="1.0" friction="0.0"/>
  </joint>
  <link name="Roller_38">
    <visual>
      <geometry>
        <cylinder length="1.219" radius="0.025"/>
      </geometry>
      <material name="black">
        <color rgba="0.1 0.1 0.1 1.0"/>
      </material>
    </visual>
    <collision>
      <geometry>
        <cylinder length="1.219" radius="0.025"/>
      </geometry>
    </collision>
    <inertial>
      <mass value="2.0"/>
      <inertia ixx="0.02" iyy="0.02" izz="0.02"/>
    </inertial>
  </link>
  <joint name="Roller_33_38_joint" type="continuous">
    <parent link="base_link"/>
    <child link="Roller_38"/>
    <origin rpy="1.5707963 0 0" xyz="-3.571875 0 1.15"/>
    <axis xyz="0 0 1"/>
    <dynamics damping="1.0" friction="0.0"/>
  </joint>
  <link name="Roller_39">
    <visual>
      <geometry>
        <cylinder length="1.219" radius="0.025"/>
      </geometry>
      <material name="black">
        <color rgba="0.1 0.1 0.1 1.0"/>
      </material>
    </visual>
    <collision>
      <geometry>
        <cylinder length="1.219" radius="0.025"/>
      </geometry>
    </collision>
    <inertial>
      <mass value="2.0"/>
      <inertia ixx="0.02" iyy="0.02" izz="0.02"/>
    </inertial>
  </link>
  <joint name="Roller_33_39_joint" type="continuous">
    <parent link="base_link"/>
    <child link="Roller_39"/>
    <origin rpy="1.5707963 0 0" xyz="-3.667125 0 1.15"/>
    <axis xyz="0 0 1"/>
    <dynamics damping="1.0" friction="0.0"/>
  </joint>
  <link name="Roller_40">
    <visual>
      <geometry>
        <cylinder length="1.219" radius="0.025"/>
      </geometry>
      <material name="black">
        <color rgba="0.1 0.1 0.1 1.0"/>
      </material>
    </visual>
    <collision>
      <geometry>
        <cylinder length="1.219" radius="0.025"/>
      </geometry>
    </collision>
    <inertial>
      <mass value="2.0"/>
      <inertia ixx="0.02" iyy="0.02" izz="0.02"/>
    </inertial>
  </link>
  <joint name="Roller_33_40_joint" type="continuous">
    <parent link="base_link"/>
    <child link="Roller_40"/>
    <origin rpy="1.5707963 0 0" xyz="-3.762375 0 1.15"/>
    <axis xyz="0 0 1"/>
    <dynamics damping="1.0" friction="0.0"/>
  </joint>
  <link name="Roller_41">
    <visual>
      <geometry>
        <cylinder length="1.219" radius="0.025"/>
      </geometry>
      <material name="black">
        <color rgba="0.1 0.1 0.1 1.0"/>
      </material>
    </visual>
    <collision>
      <geometry>
        <cylinder length="1.219" radius="0.025"/>
      </geometry>
    </collision>
    <inertial>
      <mass value="2.0"/>
      <inertia ixx="0.02" iyy="0.02" izz="0.02"/>
    </inertial>
  </link>
  <joint name="Roller_33_41_joint" type="continuous">
    <parent link="base_link"/>
    <child link="Roller_41"/>
    <origin rpy="1.5707963 0 0" xyz="-3.857625 0 1.15"/>
    <axis xyz="0 0 1"/>
    <dynamics damping="1.0" friction="0.0"/>
  </joint>
  <link name="Roller_42">
    <visual>
      <geometry>
        <cylinder length="1.219" radius="0.025"/>
      </geometry>
      <material name="black">
        <color rgba="0.1 0.1 0.1 1.0"/>
      </material>
    </visual>
    <collision>
      <geometry>
        <cylinder length="1.219" radius="0.025"/>
      </geometry>
    </collision>
    <inertial>
      <mass value="2.0"/>
      <inertia ixx="0.02" iyy="0.02" izz="0.02"/>
    </inertial>
  </link>
  <joint name="Roller_33_42_joint" type="continuous">
    <parent link="base_link"/>
    <child link="Roller_42"/>
    <origin rpy="1.5707963 0 0" xyz="-3.952875 0 1.15"/>
    <axis xyz="0 0 1"/>
    <dynamics damping="1.0" friction="0.0"/>
  </joint>
  <link name="Roller_43">
    <visual>
      <geometry>
        <cylinder length="1.219" radius="0.025"/>
      </geometry>
      <material name="black">
        <color rgba="0.1 0.1 0.1 1.0"/>
      </material>
    </visual>
    <collision>
      <geometry>
        <cylinder length="1.219" radius="0.025"/>
      </geometry>
    </collision>
    <inertial>
      <mass value="2.0"/>
      <inertia ixx="0.02" iyy="0.02" izz="0.02"/>
    </inertial>
  </link>
  <joint name="Roller_33_43_joint" type="continuous">
    <parent link="base_link"/>
    <child link="Roller_43"/>
    <origin rpy="1.5707963 0 0" xyz="-4.048125 0 1.15"/>
    <axis xyz="0 0 1"/>
    <dynamics damping="1.0" friction="0.0"/>
  </joint>
  <link name="Roller_44">
    <visual>
      <geometry>
        <cylinder length="1.219" radius="0.025"/>
      </geometry>
      <material name="black">
        <color rgba="0.1 0.1 0.1 1.0"/>
      </material>
    </visual>
    <collision>
      <geometry>
        <cylinder length="1.219" radius="0.025"/>
      </geometry>
    </collision>
    <inertial>
      <mass value="2.0"/>
      <inertia ixx="0.02" iyy="0.02" izz="0.02"/>
    </inertial>
  </link>
  <joint name="Roller_33_44_joint" type="continuous">
    <parent link="base_link"/>
    <child link="Roller_44"/>
    <origin rpy="1.5707963 0 0" xyz="-4.143375 0 1.15"/>
    <axis xyz="0 0 1"/>
    <dynamics damping="1.0" friction="0.0"/>
  </joint>
  <link name="Roller_45">
    <visual>
      <geometry>
        <cylinder length="1.219" radius="0.025"/>
      </geometry>
      <material name="black">
        <color rgba="0.1 0.1 0.1 1.0"/>
      </material>
    </visual>
    <collision>
      <geometry>
        <cylinder length="1.219" radius="0.025"/>
      </geometry>
    </collision>
    <inertial>
      <mass value="2.0"/>
      <inertia ixx="0.02" iyy="0.02" izz="0.02"/>
    </inertial>
  </link>
  <joint name="Roller_33_45_joint" type="continuous">
    <parent link="base_link"/>
    <child link="Roller_45"/>
    <origin rpy="1.5707963 0 0" xyz="-4.238625 0 1.15"/>
    <axis xyz="0 0 1"/>
    <dynamics damping="1.0" friction="0.0"/>
  </joint>
  <link name="Roller_46">
    <visual>
      <geometry>
        <cylinder length="1.219" radius="0.025"/>
      </geometry>
      <material name="black">
        <color rgba="0.1 0.1 0.1 1.0"/>
      </material>
    </visual>
    <collision>
      <geometry>
        <cylinder length="1.219" radius="0.025"/>
      </geometry>
    </collision>
    <inertial>
      <mass value="2.0"/>
      <inertia ixx="0.02" iyy="0.02" izz="0.02"/>
    </inertial>
  </link>
  <joint name="Roller_33_46_joint" type="continuous">
    <parent link="base_link"/>
    <child link="Roller_46"/>
    <origin rpy="1.5707963 0 0" xyz="-4.333875 0 1.15"/>
    <axis xyz="0 0 1"/>
    <dynamics damping="1.0" friction="0.0"/>
  </joint>
  <link name="Roller_47">
    <visual>
      <geometry>
        <cylinder length="1.219" radius="0.025"/>
      </geometry>
      <material name="black">
        <color rgba="0.1 0.1 0.1 1.0"/>
      </material>
    </visual>
    <collision>
      <geometry>
        <cylinder length="1.219" radius="0.025"/>
      </geometry>
    </collision>
    <inertial>
      <mass value="2.0"/>
      <inertia ixx="0.02" iyy="0.02" izz="0.02"/>
    </inertial>
  </link>
  <joint name="Roller_33_47_joint" type="continuous">
    <parent link="base_link"/>
    <child link="Roller_47"/>
    <origin rpy="1.5707963 0 0" xyz="-4.429125 0 1.15"/>
    <axis xyz="0 0 1"/>
    <dynamics damping="1.0" friction="0.0"/>
  </joint>
  <link name="Roller_48">
    <visual>
      <geometry>
        <cylinder length="1.219" radius="0.025"/>
      </geometry>
      <material name="black">
        <color rgba="0.1 0.1 0.1 1.0"/>
      </material>
    </visual>
    <collision>
      <geometry>
        <cylinder length="1.219" radius="0.025"/>
      </geometry>
    </collision>
    <inertial>
      <mass value="2.0"/>
      <inertia ixx="0.02" iyy="0.02" izz="0.02"/>
    </inertial>
  </link>
  <joint name="Roller_33_48_joint" type="continuous">
    <parent link="base_link"/>
    <child link="Roller_48"/>
    <origin rpy="1.5707963 0 0" xyz="-4.524375 0 1.15"/>
    <axis xyz="0 0 1"/>
    <dynamics damping="1.0" friction="0.0"/>
  </joint>
  <link name="Roller_50">
    <visual>
      <geometry>
        <cylinder length="1.219" radius="0.025"/>
      </geometry>
      <material name="black">
        <color rgba="0.1 0.1 0.1 1.0"/>
      </material>
    </visual>
    <collision>
      <geometry>
        <cylinder length="1.219" radius="0.025"/>
      </geometry>
    </collision>
    <inertial>
      <mass value="2.0"/>
      <inertia ixx="0.02" iyy="0.02" izz="0.02"/>
    </inertial>
  </link>
  <joint name="Roller_49_50_joint" type="continuous">
    <parent link="base_link"/>
    <child link="Roller_50"/>
    <origin rpy="1.5707963 0 0" xyz="-4.714875 0 1.15"/>
    <axis xyz="0 0 1"/>
    <dynamics damping="1.0" friction="0.0"/>
  </joint>
  <link name="Roller_51">
    <visual>
      <geometry>
        <cylinder length="1.219" radius="0.025"/>
      </geometry>
      <material name="black">
        <color rgba="0.1 0.1 0.1 1.0"/>
      </material>
    </visual>
    <collision>
      <geometry>
        <cylinder length="1.219" radius="0.025"/>
      </geometry>
    </collision>
    <inertial>
      <mass value="2.0"/>
      <inertia ixx="0.02" iyy="0.02" izz="0.02"/>
    </inertial>
  </link>
  <joint name="Roller_49_51_joint" type="continuous">
    <parent link="base_link"/>
    <child link="Roller_51"/>
    <origin rpy="1.5707963 0 0" xyz="-4.810125 0 1.15"/>
    <axis xyz="0 0 1"/>
    <dynamics damping="1.0" friction="0.0"/>
  </joint>
  <link name="Roller_52">
    <visual>
      <geometry>
        <cylinder length="1.219" radius="0.025"/>
      </geometry>
      <material name="black">
        <color rgba="0.1 0.1 0.1 1.0"/>
      </material>
    </visual>
    <collision>
      <geometry>
        <cylinder length="1.219" radius="0.025"/>
      </geometry>
    </collision>
    <inertial>
      <mass value="2.0"/>
      <inertia ixx="0.02" iyy="0.02" izz="0.02"/>
    </inertial>
  </link>
  <joint name="Roller_49_52_joint" type="continuous">
    <parent link="base_link"/>
    <child link="Roller_52"/>
    <origin rpy="1.5707963 0 0" xyz="-4.905375 0 1.15"/>
    <axis xyz="0 0 1"/>
    <dynamics damping="1.0" friction="0.0"/>
  </joint>
  <link name="Roller_53">
    <visual>
      <geometry>
        <cylinder length="1.219" radius="0.025"/>
      </geometry>
      <material name="black">
        <color rgba="0.1 0.1 0.1 1.0"/>
      </material>
    </visual>
    <collision>
      <geometry>
        <cylinder length="1.219" radius="0.025"/>
      </geometry>
    </collision>
    <inertial>
      <mass value="2.0"/>
      <inertia ixx="0.02" iyy="0.02" izz="0.02"/>
    </inertial>
  </link>
  <joint name="Roller_49_53_joint" type="continuous">
    <parent link="base_link"/>
    <child link="Roller_53"/>
    <origin rpy="1.5707963 0 0" xyz="-5.000625 0 1.15"/>
    <axis xyz="0 0 1"/>
    <dynamics damping="1.0" friction="0.0"/>
  </joint>
  <link name="Roller_54">
    <visual>
      <geometry>
        <cylinder length="1.219" radius="0.025"/>
      </geometry>
      <material name="black">
        <color rgba="0.1 0.1 0.1 1.0"/>
      </material>
    </visual>
    <collision>
      <geometry>
        <cylinder length="1.219" radius="0.025"/>
      </geometry>
    </collision>
    <inertial>
      <mass value="2.0"/>
      <inertia ixx="0.02" iyy="0.02" izz="0.02"/>
    </inertial>
  </link>
  <joint name="Roller_49_54_joint" type="continuous">
    <parent link="base_link"/>
    <child link="Roller_54"/>
    <origin rpy="1.5707963 0 0" xyz="-5.095875 0 1.15"/>
    <axis xyz="0 0 1"/>
    <dynamics damping="1.0" friction="0.0"/>
  </joint>
  <link name="Roller_55">
    <visual>
      <geometry>
        <cylinder length="1.219" radius="0.025"/>
      </geometry>
      <material name="black">
        <color rgba="0.1 0.1 0.1 1.0"/>
      </material>
    </visual>
    <collision>
      <geometry>
        <cylinder length="1.219" radius="0.025"/>
      </geometry>
    </collision>
    <inertial>
      <mass value="2.0"/>
      <inertia ixx="0.02" iyy="0.02" izz="0.02"/>
    </inertial>
  </link>
  <joint name="Roller_49_55_joint" type="continuous">
    <parent link="base_link"/>
    <child link="Roller_55"/>
    <origin rpy="1.5707963 0 0" xyz="-5.191125 0 1.15"/>
    <axis xyz="0 0 1"/>
    <dynamics damping="1.0" friction="0.0"/>
  </joint>
  <link name="Roller_56">
    <visual>
      <geometry>
        <cylinder length="1.219" radius="0.025"/>
      </geometry>
      <material name="black">
        <color rgba="0.1 0.1 0.1 1.0"/>
      </material>
    </visual>
    <collision>
      <geometry>
        <cylinder length="1.219" radius="0.025"/>
      </geometry>
    </collision>
    <inertial>
      <mass value="2.0"/>
      <inertia ixx="0.02" iyy="0.02" izz="0.02"/>
    </inertial>
  </link>
  <joint name="Roller_49_56_joint" type="continuous">
    <parent link="base_link"/>
    <child link="Roller_56"/>
    <origin rpy="1.5707963 0 0" xyz="-5.2863750000000005 0 1.15"/>
    <axis xyz="0 0 1"/>
    <dynamics damping="1.0" friction="0.0"/>
  </joint>
  <link name="Roller_57">
    <visual>
      <geometry>
        <cylinder length="1.219" radius="0.025"/>
      </geometry>
      <material name="black">
        <color rgba="0.1 0.1 0.1 1.0"/>
      </material>
    </visual>
    <collision>
      <geometry>
        <cylinder length="1.219" radius="0.025"/>
      </geometry>
    </collision>
    <inertial>
      <mass value="2.0"/>
      <inertia ixx="0.02" iyy="0.02" izz="0.02"/>
    </inertial>
  </link>
  <joint name="Roller_49_57_joint" type="continuous">
    <parent link="base_link"/>
    <child link="Roller_57"/>
    <origin rpy="1.5707963 0 0" xyz="-5.381625 0 1.15"/>
    <axis xyz="0 0 1"/>
    <dynamics damping="1.0" friction="0.0"/>
  </joint>
  <link name="Roller_58">
    <visual>
      <geometry>
        <cylinder length="1.219" radius="0.025"/>
      </geometry>
      <material name="black">
        <color rgba="0.1 0.1 0.1 1.0"/>
      </material>
    </visual>
    <collision>
      <geometry>
        <cylinder length="1.219" radius="0.025"/>
      </geometry>
    </collision>
    <inertial>
      <mass value="2.0"/>
      <inertia ixx="0.02" iyy="0.02" izz="0.02"/>
    </inertial>
  </link>
  <joint name="Roller_49_58_joint" type="continuous">
    <parent link="base_link"/>
    <child link="Roller_58"/>
    <origin rpy="1.5707963 0 0" xyz="-5.476875 0 1.15"/>
    <axis xyz="0 0 1"/>
    <dynamics damping="1.0" friction="0.0"/>
  </joint>
  <link name="Roller_59">
    <visual>
      <geometry>
        <cylinder length="1.219" radius="0.025"/>
      </geometry>
      <material name="black">
        <color rgba="0.1 0.1 0.1 1.0"/>
      </material>
    </visual>
    <collision>
      <geometry>
        <cylinder length="1.219" radius="0.025"/>
      </geometry>
    </collision>
    <inertial>
      <mass value="2.0"/>
      <inertia ixx="0.02" iyy="0.02" izz="0.02"/>
    </inertial>
  </link>
  <joint name="Roller_49_59_joint" type="continuous">
    <parent link="base_link"/>
    <child link="Roller_59"/>
    <origin rpy="1.5707963 0 0" xyz="-5.572125 0 1.15"/>
    <axis xyz="0 0 1"/>
    <dynamics damping="1.0" friction="0.0"/>
  </joint>
  <link name="Roller_60">
    <visual>
      <geometry>
        <cylinder length="1.219" radius="0.025"/>
      </geometry>
      <material name="black">
        <color rgba="0.1 0.1 0.1 1.0"/>
      </material>
    </visual>
    <collision>
      <geometry>
        <cylinder length="1.219" radius="0.025"/>
      </geometry>
    </collision>
    <inertial>
      <mass value="2.0"/>
      <inertia ixx="0.02" iyy="0.02" izz="0.02"/>
    </inertial>
  </link>
  <joint name="Roller_49_60_joint" type="continuous">
    <parent link="base_link"/>
    <child link="Roller_60"/>
    <origin rpy="1.5707963 0 0" xyz="-5.667375 0 1.15"/>
    <axis xyz="0 0 1"/>
    <dynamics damping="1.0" friction="0.0"/>
  </joint>
  <link name="Roller_61">
    <visual>
      <geometry>
        <cylinder length="1.219" radius="0.025"/>
      </geometry>
      <material name="black">
        <color rgba="0.1 0.1 0.1 1.0"/>
      </material>
    </visual>
    <collision>
      <geometry>
        <cylinder length="1.219" radius="0.025"/>
      </geometry>
    </collision>
    <inertial>
      <mass value="2.0"/>
      <inertia ixx="0.02" iyy="0.02" izz="0.02"/>
    </inertial>
  </link>
  <joint name="Roller_49_61_joint" type="continuous">
    <parent link="base_link"/>
    <child link="Roller_61"/>
    <origin rpy="1.5707963 0 0" xyz="-5.762625 0 1.15"/>
    <axis xyz="0 0 1"/>
    <dynamics damping="1.0" friction="0.0"/>
  </joint>
  <link name="Roller_62">
    <visual>
      <geometry>
        <cylinder length="1.219" radius="0.025"/>
      </geometry>
      <material name="black">
        <color rgba="0.1 0.1 0.1 1.0"/>
      </material>
    </visual>
    <collision>
      <geometry>
        <cylinder length="1.219" radius="0.025"/>
      </geometry>
    </collision>
    <inertial>
      <mass value="2.0"/>
      <inertia ixx="0.02" iyy="0.02" izz="0.02"/>
    </inertial>
  </link>
  <joint name="Roller_49_62_joint" type="continuous">
    <parent link="base_link"/>
    <child link="Roller_62"/>
    <origin rpy="1.5707963 0 0" xyz="-5.857875 0 1.15"/>
    <axis xyz="0 0 1"/>
    <dynamics damping="1.0" friction="0.0"/>
  </joint>
  <link name="Roller_63">
    <visual>
      <geometry>
        <cylinder length="1.219" radius="0.025"/>
      </geometry>
      <material name="black">
        <color rgba="0.1 0.1 0.1 1.0"/>
      </material>
    </visual>
    <collision>
      <geometry>
        <cylinder length="1.219" radius="0.025"/>
      </geometry>
    </collision>
    <inertial>
      <mass value="2.0"/>
      <inertia ixx="0.02" iyy="0.02" izz="0.02"/>
    </inertial>
  </link>
  <joint name="Roller_49_63_joint" type="continuous">
    <parent link="base_link"/>
    <child link="Roller_63"/>
    <origin rpy="1.5707963 0 0" xyz="-5.953125 0 1.15"/>
    <axis xyz="0 0 1"/>
    <dynamics damping="1.0" friction="0.0"/>
  </joint>
  <link name="Roller_64">
    <visual>
      <geometry>
        <cylinder length="1.219" radius="0.025"/>
      </geometry>
      <material name="black">
        <color rgba="0.1 0.1 0.1 1.0"/>
      </material>
    </visual>
    <collision>
      <geometry>
        <cylinder length="1.219" radius="0.025"/>
      </geometry>
    </collision>
    <inertial>
      <mass value="2.0"/>
      <inertia ixx="0.02" iyy="0.02" izz="0.02"/>
    </inertial>
  </link>
  <joint name="Roller_49_64_joint" type="continuous">
    <parent link="base_link"/>
    <child link="Roller_64"/>
    <origin rpy="1.5707963 0 0" xyz="-6.048375 0 1.15"/>
    <axis xyz="0 0 1"/>
    <dynamics damping="1.0" friction="0.0"/>
  </joint>
  <link name="Roller_66">
    <visual>
      <geometry>
        <cylinder length="1.219" radius="0.025"/>
      </geometry>
      <material name="black">
        <color rgba="0.1 0.1 0.1 1.0"/>
      </material>
    </visual>
    <collision>
      <geometry>
        <cylinder length="1.219" radius="0.025"/>
      </geometry>
    </collision>
    <inertial>
      <mass value="2.0"/>
      <inertia ixx="0.02" iyy="0.02" izz="0.02"/>
    </inertial>
  </link>
  <joint name="Roller_65_66_joint" type="continuous">
    <parent link="base_link"/>
    <child link="Roller_66"/>
    <origin rpy="1.5707963 0 0" xyz="-6.238875 0 1.15"/>
    <axis xyz="0 0 1"/>
    <dynamics damping="1.0" friction="0.0"/>
  </joint>
  <link name="Roller_67">
    <visual>
      <geometry>
        <cylinder length="1.219" radius="0.025"/>
      </geometry>
      <material name="black">
        <color rgba="0.1 0.1 0.1 1.0"/>
      </material>
    </visual>
    <collision>
      <geometry>
        <cylinder length="1.219" radius="0.025"/>
      </geometry>
    </collision>
    <inertial>
      <mass value="2.0"/>
      <inertia ixx="0.02" iyy="0.02" izz="0.02"/>
    </inertial>
  </link>
  <joint name="Roller_65_67_joint" type="continuous">
    <parent link="base_link"/>
    <child link="Roller_67"/>
    <origin rpy="1.5707963 0 0" xyz="-6.334125 0 1.15"/>
    <axis xyz="0 0 1"/>
    <dynamics damping="1.0" friction="0.0"/>
  </joint>
  <link name="Roller_68">
    <visual>
      <geometry>
        <cylinder length="1.219" radius="0.025"/>
      </geometry>
      <material name="black">
        <color rgba="0.1 0.1 0.1 1.0"/>
      </material>
    </visual>
    <collision>
      <geometry>
        <cylinder length="1.219" radius="0.025"/>
      </geometry>
    </collision>
    <inertial>
      <mass value="2.0"/>
      <inertia ixx="0.02" iyy="0.02" izz="0.02"/>
    </inertial>
  </link>
  <joint name="Roller_65_68_joint" type="continuous">
    <parent link="base_link"/>
    <child link="Roller_68"/>
    <origin rpy="1.5707963 0 0" xyz="-6.429375 0 1.15"/>
    <axis xyz="0 0 1"/>
    <dynamics damping="1.0" friction="0.0"/>
  </joint>
  <link name="Roller_69">
    <visual>
      <geometry>
        <cylinder length="1.219" radius="0.025"/>
      </geometry>
      <material name="black">
        <color rgba="0.1 0.1 0.1 1.0"/>
      </material>
    </visual>
    <collision>
      <geometry>
        <cylinder length="1.219" radius="0.025"/>
      </geometry>
    </collision>
    <inertial>
      <mass value="2.0"/>
      <inertia ixx="0.02" iyy="0.02" izz="0.02"/>
    </inertial>
  </link>
  <joint name="Roller_65_69_joint" type="continuous">
    <parent link="base_link"/>
    <child link="Roller_69"/>
    <origin rpy="1.5707963 0 0" xyz="-6.524625 0 1.15"/>
    <axis xyz="0 0 1"/>
    <dynamics damping="1.0" friction="0.0"/>
  </joint>
  <link name="Roller_70">
    <visual>
      <geometry>
        <cylinder length="1.219" radius="0.025"/>
      </geometry>
      <material name="black">
        <color rgba="0.1 0.1 0.1 1.0"/>
      </material>
    </visual>
    <collision>
      <geometry>
        <cylinder length="1.219" radius="0.025"/>
      </geometry>
    </collision>
    <inertial>
      <mass value="2.0"/>
      <inertia ixx="0.02" iyy="0.02" izz="0.02"/>
    </inertial>
  </link>
  <joint name="Roller_65_70_joint" type="continuous">
    <parent link="base_link"/>
    <child link="Roller_70"/>
    <origin rpy="1.5707963 0 0" xyz="-6.619875 0 1.15"/>
    <axis xyz="0 0 1"/>
    <dynamics damping="1.0" friction="0.0"/>
  </joint>
  <link name="Roller_71">
    <visual>
      <geometry>
        <cylinder length="1.219" radius="0.025"/>
      </geometry>
      <material name="black">
        <color rgba="0.1 0.1 0.1 1.0"/>
      </material>
    </visual>
    <collision>
      <geometry>
        <cylinder length="1.219" radius="0.025"/>
      </geometry>
    </collision>
    <inertial>
      <mass value="2.0"/>
      <inertia ixx="0.02" iyy="0.02" izz="0.02"/>
    </inertial>
  </link>
  <joint name="Roller_65_71_joint" type="continuous">
    <parent link="base_link"/>
    <child link="Roller_71"/>
    <origin rpy="1.5707963 0 0" xyz="-6.7151250000000005 0 1.15"/>
    <axis xyz="0 0 1"/>
    <dynamics damping="1.0" friction="0.0"/>
  </joint>
  <link name="Roller_72">
    <visual>
      <geometry>
        <cylinder length="1.219" radius="0.025"/>
      </geometry>
      <material name="black">
        <color rgba="0.1 0.1 0.1 1.0"/>
      </material>
    </visual>
    <collision>
      <geometry>
        <cylinder length="1.219" radius="0.025"/>
      </geometry>
    </collision>
    <inertial>
      <mass value="2.0"/>
      <inertia ixx="0.02" iyy="0.02" izz="0.02"/>
    </inertial>
  </link>
  <joint name="Roller_65_72_joint" type="continuous">
    <parent link="base_link"/>
    <child link="Roller_72"/>
    <origin rpy="1.5707963 0 0" xyz="-6.8103750000000005 0 1.15"/>
    <axis xyz="0 0 1"/>
    <dynamics damping="1.0" friction="0.0"/>
  </joint>
  <link name="Roller_73">
    <visual>
      <geometry>
        <cylinder length="1.219" radius="0.025"/>
      </geometry>
      <material name="black">
        <color rgba="0.1 0.1 0.1 1.0"/>
      </material>
    </visual>
    <collision>
      <geometry>
        <cylinder length="1.219" radius="0.025"/>
      </geometry>
    </collision>
    <inertial>
      <mass value="2.0"/>
      <inertia ixx="0.02" iyy="0.02" izz="0.02"/>
    </inertial>
  </link>
  <joint name="Roller_65_73_joint" type="continuous">
    <parent link="base_link"/>
    <child link="Roller_73"/>
    <origin rpy="1.5707963 0 0" xyz="-6.905625000000001 0 1.15"/>
    <axis xyz="0 0 1"/>
    <dynamics damping="1.0" friction="0.0"/>
  </joint>
  <link name="Roller_74">
    <visual>
      <geometry>
        <cylinder length="1.219" radius="0.025"/>
      </geometry>
      <material name="black">
        <color rgba="0.1 0.1 0.1 1.0"/>
      </material>
    </visual>
    <collision>
      <geometry>
        <cylinder length="1.219" radius="0.025"/>
      </geometry>
    </collision>
    <inertial>
      <mass value="2.0"/>
      <inertia ixx="0.02" iyy="0.02" izz="0.02"/>
    </inertial>
  </link>
  <joint name="Roller_65_74_joint" type="continuous">
    <parent link="base_link"/>
    <child link="Roller_74"/>
    <origin rpy="1.5707963 0 0" xyz="-7.000875 0 1.15"/>
    <axis xyz="0 0 1"/>
    <dynamics damping="1.0" friction="0.0"/>
  </joint>
  <link name="Roller_75">
    <visual>
      <geometry>
        <cylinder length="1.219" radius="0.025"/>
      </geometry>
      <material name="black">
        <color rgba="0.1 0.1 0.1 1.0"/>
      </material>
    </visual>
    <collision>
      <geometry>
        <cylinder length="1.219" radius="0.025"/>
      </geometry>
    </collision>
    <inertial>
      <mass value="2.0"/>
      <inertia ixx="0.02" iyy="0.02" izz="0.02"/>
    </inertial>
  </link>
  <joint name="Roller_65_75_joint" type="continuous">
    <parent link="base_link"/>
    <child link="Roller_75"/>
    <origin rpy="1.5707963 0 0" xyz="-7.096125 0 1.15"/>
    <axis xyz="0 0 1"/>
    <dynamics damping="1.0" friction="0.0"/>
  </joint>
  <link name="Roller_76">
    <visual>
      <geometry>
        <cylinder length="1.219" radius="0.025"/>
      </geometry>
      <material name="black">
        <color rgba="0.1 0.1 0.1 1.0"/>
      </material>
    </visual>
    <collision>
      <geometry>
        <cylinder length="1.219" radius="0.025"/>
      </geometry>
    </collision>
    <inertial>
      <mass value="2.0"/>
      <inertia ixx="0.02" iyy="0.02" izz="0.02"/>
    </inertial>
  </link>
  <joint name="Roller_65_76_joint" type="continuous">
    <parent link="base_link"/>
    <child link="Roller_76"/>
    <origin rpy="1.5707963 0 0" xyz="-7.191375 0 1.15"/>
    <axis xyz="0 0 1"/>
    <dynamics damping="1.0" friction="0.0"/>
  </joint>
  <link name="Roller_77">
    <visual>
      <geometry>
        <cylinder length="1.219" radius="0.025"/>
      </geometry>
      <material name="black">
        <color rgba="0.1 0.1 0.1 1.0"/>
      </material>
    </visual>
    <collision>
      <geometry>
        <cylinder length="1.219" radius="0.025"/>
      </geometry>
    </collision>
    <inertial>
      <mass value="2.0"/>
      <inertia ixx="0.02" iyy="0.02" izz="0.02"/>
    </inertial>
  </link>
  <joint name="Roller_65_77_joint" type="continuous">
    <parent link="base_link"/>
    <child link="Roller_77"/>
    <origin rpy="1.5707963 0 0" xyz="-7.286625 0 1.15"/>
    <axis xyz="0 0 1"/>
    <dynamics damping="1.0" friction="0.0"/>
  </joint>
  <link name="Roller_78">
    <visual>
      <geometry>
        <cylinder length="1.219" radius="0.025"/>
      </geometry>
      <material name="black">
        <color rgba="0.1 0.1 0.1 1.0"/>
      </material>
    </visual>
    <collision>
      <geometry>
        <cylinder length="1.219" radius="0.025"/>
      </geometry>
    </collision>
    <inertial>
      <mass value="2.0"/>
      <inertia ixx="0.02" iyy="0.02" izz="0.02"/>
    </inertial>
  </link>
  <joint name="Roller_65_78_joint" type="continuous">
    <parent link="base_link"/>
    <child link="Roller_78"/>
    <origin rpy="1.5707963 0 0" xyz="-7.381875 0 1.15"/>
    <axis xyz="0 0 1"/>
    <dynamics damping="1.0" friction="0.0"/>
  </joint>
  <link name="Roller_79">
    <visual>
      <geometry>
        <cylinder length="1.219" radius="0.025"/>
      </geometry>
      <material name="black">
        <color rgba="0.1 0.1 0.1 1.0"/>
      </material>
    </visual>
    <collision>
      <geometry>
        <cylinder length="1.219" radius="0.025"/>
      </geometry>
    </collision>
    <inertial>
      <mass value="2.0"/>
      <inertia ixx="0.02" iyy="0.02" izz="0.02"/>
    </inertial>
  </link>
  <joint name="Roller_65_79_joint" type="continuous">
    <parent link="base_link"/>
    <child link="Roller_79"/>
    <origin rpy="1.5707963 0 0" xyz="-7.477125 0 1.15"/>
    <axis xyz="0 0 1"/>
    <dynamics damping="1.0" friction="0.0"/>
  </joint>
  <link name="Roller_80">
    <visual>
      <geometry>
        <cylinder length="1.219" radius="0.025"/>
      </geometry>
      <material name="black">
        <color rgba="0.1 0.1 0.1 1.0"/>
      </material>
    </visual>
    <collision>
      <geometry>
        <cylinder length="1.219" radius="0.025"/>
      </geometry>
    </collision>
    <inertial>
      <mass value="2.0"/>
      <inertia ixx="0.02" iyy="0.02" izz="0.02"/>
    </inertial>
  </link>
  <joint name="Roller_65_80_joint" type="continuous">
    <parent link="base_link"/>
    <child link="Roller_80"/>
    <origin rpy="1.5707963 0 0" xyz="-7.572375 0 1.15"/>
    <axis xyz="0 0 1"/>
    <dynamics damping="1.0" friction="0.0"/>
  </joint>
  <link name="Roller_82">
    <visual>
      <geometry>
        <cylinder length="1.219" radius="0.025"/>
      </geometry>
      <material name="black">
        <color rgba="0.1 0.1 0.1 1.0"/>
      </material>
    </visual>
    <collision>
      <geometry>
        <cylinder length="1.219" radius="0.025"/>
      </geometry>
    </collision>
    <inertial>
      <mass value="2.0"/>
      <inertia ixx="0.02" iyy="0.02" izz="0.02"/>
    </inertial>
  </link>
  <joint name="Roller_81_82_joint" type="continuous">
    <parent link="base_link"/>
    <child link="Roller_82"/>
    <origin rpy="1.5707963 0 0" xyz="-7.762875 0 1.15"/>
    <axis xyz="0 0 1"/>
    <dynamics damping="1.0" friction="0.0"/>
  </joint>
  <link name="Roller_83">
    <visual>
      <geometry>
        <cylinder length="1.219" radius="0.025"/>
      </geometry>
      <material name="black">
        <color rgba="0.1 0.1 0.1 1.0"/>
      </material>
    </visual>
    <collision>
      <geometry>
        <cylinder length="1.219" radius="0.025"/>
      </geometry>
    </collision>
    <inertial>
      <mass value="2.0"/>
      <inertia ixx="0.02" iyy="0.02" izz="0.02"/>
    </inertial>
  </link>
  <joint name="Roller_81_83_joint" type="continuous">
    <parent link="base_link"/>
    <child link="Roller_83"/>
    <origin rpy="1.5707963 0 0" xyz="-7.858125 0 1.15"/>
    <axis xyz="0 0 1"/>
    <dynamics damping="1.0" friction="0.0"/>
  </joint>
  <link name="Roller_84">
    <visual>
      <geometry>
        <cylinder length="1.219" radius="0.025"/>
      </geometry>
      <material name="black">
        <color rgba="0.1 0.1 0.1 1.0"/>
      </material>
    </visual>
    <collision>
      <geometry>
        <cylinder length="1.219" radius="0.025"/>
      </geometry>
    </collision>
    <inertial>
      <mass value="2.0"/>
      <inertia ixx="0.02" iyy="0.02" izz="0.02"/>
    </inertial>
  </link>
  <joint name="Roller_81_84_joint" type="continuous">
    <parent link="base_link"/>
    <child link="Roller_84"/>
    <origin rpy="1.5707963 0 0" xyz="-7.953375 0 1.15"/>
    <axis xyz="0 0 1"/>
    <dynamics damping="1.0" friction="0.0"/>
  </joint>
  <link name="Roller_85">
    <visual>
      <geometry>
        <cylinder length="1.219" radius="0.025"/>
      </geometry>
      <material name="black">
        <color rgba="0.1 0.1 0.1 1.0"/>
      </material>
    </visual>
    <collision>
      <geometry>
        <cylinder length="1.219" radius="0.025"/>
      </geometry>
    </collision>
    <inertial>
      <mass value="2.0"/>
      <inertia ixx="0.02" iyy="0.02" izz="0.02"/>
    </inertial>
  </link>
  <joint name="Roller_81_85_joint" type="continuous">
    <parent link="base_link"/>
    <child link="Roller_85"/>
    <origin rpy="1.5707963 0 0" xyz="-8.048625 0 1.15"/>
    <axis xyz="0 0 1"/>
    <dynamics damping="1.0" friction="0.0"/>
  </joint>
  <link name="Roller_86">
    <visual>
      <geometry>
        <cylinder length="1.219" radius="0.025"/>
      </geometry>
      <material name="black">
        <color rgba="0.1 0.1 0.1 1.0"/>
      </material>
    </visual>
    <collision>
      <geometry>
        <cylinder length="1.219" radius="0.025"/>
      </geometry>
    </collision>
    <inertial>
      <mass value="2.0"/>
      <inertia ixx="0.02" iyy="0.02" izz="0.02"/>
    </inertial>
  </link>
  <joint name="Roller_81_86_joint" type="continuous">
    <parent link="base_link"/>
    <child link="Roller_86"/>
    <origin rpy="1.5707963 0 0" xyz="-8.143875 0 1.15"/>
    <axis xyz="0 0 1"/>
    <dynamics damping="1.0" friction="0.0"/>
  </joint>
  <link name="Roller_87">
    <visual>
      <geometry>
        <cylinder length="1.219" radius="0.025"/>
      </geometry>
      <material name="black">
        <color rgba="0.1 0.1 0.1 1.0"/>
      </material>
    </visual>
    <collision>
      <geometry>
        <cylinder length="1.219" radius="0.025"/>
      </geometry>
    </collision>
    <inertial>
      <mass value="2.0"/>
      <inertia ixx="0.02" iyy="0.02" izz="0.02"/>
    </inertial>
  </link>
  <joint name="Roller_81_87_joint" type="continuous">
    <parent link="base_link"/>
    <child link="Roller_87"/>
    <origin rpy="1.5707963 0 0" xyz="-8.239125 0 1.15"/>
    <axis xyz="0 0 1"/>
    <dynamics damping="1.0" friction="0.0"/>
  </joint>
  <link name="Roller_88">
    <visual>
      <geometry>
        <cylinder length="1.219" radius="0.025"/>
      </geometry>
      <material name="black">
        <color rgba="0.1 0.1 0.1 1.0"/>
      </material>
    </visual>
    <collision>
      <geometry>
        <cylinder length="1.219" radius="0.025"/>
      </geometry>
    </collision>
    <inertial>
      <mass value="2.0"/>
      <inertia ixx="0.02" iyy="0.02" izz="0.02"/>
    </inertial>
  </link>
  <joint name="Roller_81_88_joint" type="continuous">
    <parent link="base_link"/>
    <child link="Roller_88"/>
    <origin rpy="1.5707963 0 0" xyz="-8.334375 0 1.15"/>
    <axis xyz="0 0 1"/>
    <dynamics damping="1.0" friction="0.0"/>
  </joint>
  <link name="Roller_89">
    <visual>
      <geometry>
        <cylinder length="1.219" radius="0.025"/>
      </geometry>
      <material name="black">
        <color rgba="0.1 0.1 0.1 1.0"/>
      </material>
    </visual>
    <collision>
      <geometry>
        <cylinder length="1.219" radius="0.025"/>
      </geometry>
    </collision>
    <inertial>
      <mass value="2.0"/>
      <inertia ixx="0.02" iyy="0.02" izz="0.02"/>
    </inertial>
  </link>
  <joint name="Roller_81_89_joint" type="continuous">
    <parent link="base_link"/>
    <child link="Roller_89"/>
    <origin rpy="1.5707963 0 0" xyz="-8.429625 0 1.15"/>
    <axis xyz="0 0 1"/>
    <dynamics damping="1.0" friction="0.0"/>
  </joint>
  <link name="Roller_90">
    <visual>
      <geometry>
        <cylinder length="1.219" radius="0.025"/>
      </geometry>
      <material name="black">
        <color rgba="0.1 0.1 0.1 1.0"/>
      </material>
    </visual>
    <collision>
      <geometry>
        <cylinder length="1.219" radius="0.025"/>
      </geometry>
    </collision>
    <inertial>
      <mass value="2.0"/>
      <inertia ixx="0.02" iyy="0.02" izz="0.02"/>
    </inertial>
  </link>
  <joint name="Roller_81_90_joint" type="continuous">
    <parent link="base_link"/>
    <child link="Roller_90"/>
    <origin rpy="1.5707963 0 0" xyz="-8.524875 0 1.15"/>
    <axis xyz="0 0 1"/>
    <dynamics damping="1.0" friction="0.0"/>
  </joint>
  <link name="Roller_91">
    <visual>
      <geometry>
        <cylinder length="1.219" radius="0.025"/>
      </geometry>
      <material name="black">
        <color rgba="0.1 0.1 0.1 1.0"/>
      </material>
    </visual>
    <collision>
      <geometry>
        <cylinder length="1.219" radius="0.025"/>
      </geometry>
    </collision>
    <inertial>
      <mass value="2.0"/>
      <inertia ixx="0.02" iyy="0.02" izz="0.02"/>
    </inertial>
  </link>
  <joint name="Roller_81_91_joint" type="continuous">
    <parent link="base_link"/>
    <child link="Roller_91"/>
    <origin rpy="1.5707963 0 0" xyz="-8.620125 0 1.15"/>
    <axis xyz="0 0 1"/>
    <dynamics damping="1.0" friction="0.0"/>
  </joint>
  <link name="Roller_92">
    <visual>
      <geometry>
        <cylinder length="1.219" radius="0.025"/>
      </geometry>
      <material name="black">
        <color rgba="0.1 0.1 0.1 1.0"/>
      </material>
    </visual>
    <collision>
      <geometry>
        <cylinder length="1.219" radius="0.025"/>
      </geometry>
    </collision>
    <inertial>
      <mass value="2.0"/>
      <inertia ixx="0.02" iyy="0.02" izz="0.02"/>
    </inertial>
  </link>
  <joint name="Roller_81_92_joint" type="continuous">
    <parent link="base_link"/>
    <child link="Roller_92"/>
    <origin rpy="1.5707963 0 0" xyz="-8.715375 0 1.15"/>
    <axis xyz="0 0 1"/>
    <dynamics damping="1.0" friction="0.0"/>
  </joint>
  <link name="Roller_93">
    <visual>
      <geometry>
        <cylinder length="1.219" radius="0.025"/>
      </geometry>
      <material name="black">
        <color rgba="0.1 0.1 0.1 1.0"/>
      </material>
    </visual>
    <collision>
      <geometry>
        <cylinder length="1.219" radius="0.025"/>
      </geometry>
    </collision>
    <inertial>
      <mass value="2.0"/>
      <inertia ixx="0.02" iyy="0.02" izz="0.02"/>
    </inertial>
  </link>
  <joint name="Roller_81_93_joint" type="continuous">
    <parent link="base_link"/>
    <child link="Roller_93"/>
    <origin rpy="1.5707963 0 0" xyz="-8.810625 0 1.15"/>
    <axis xyz="0 0 1"/>
    <dynamics damping="1.0" friction="0.0"/>
  </joint>
  <link name="Roller_94">
    <visual>
      <geometry>
        <cylinder length="1.219" radius="0.025"/>
      </geometry>
      <material name="black">
        <color rgba="0.1 0.1 0.1 1.0"/>
      </material>
    </visual>
    <collision>
      <geometry>
        <cylinder length="1.219" radius="0.025"/>
      </geometry>
    </collision>
    <inertial>
      <mass value="2.0"/>
      <inertia ixx="0.02" iyy="0.02" izz="0.02"/>
    </inertial>
  </link>
  <joint name="Roller_81_94_joint" type="continuous">
    <parent link="base_link"/>
    <child link="Roller_94"/>
    <origin rpy="1.5707963 0 0" xyz="-8.905875 0 1.15"/>
    <axis xyz="0 0 1"/>
    <dynamics damping="1.0" friction="0.0"/>
  </joint>
  <link name="Roller_95">
    <visual>
      <geometry>
        <cylinder length="1.219" radius="0.025"/>
      </geometry>
      <material name="black">
        <color rgba="0.1 0.1 0.1 1.0"/>
      </material>
    </visual>
    <collision>
      <geometry>
        <cylinder length="1.219" radius="0.025"/>
      </geometry>
    </collision>
    <inertial>
      <mass value="2.0"/>
      <inertia ixx="0.02" iyy="0.02" izz="0.02"/>
    </inertial>
  </link>
  <joint name="Roller_81_95_joint" type="continuous">
    <parent link="base_link"/>
    <child link="Roller_95"/>
    <origin rpy="1.5707963 0 0" xyz="-9.001125 0 1.15"/>
    <axis xyz="0 0 1"/>
    <dynamics damping="1.0" friction="0.0"/>
  </joint>
  <link name="Roller_96">
    <visual>
      <geometry>
        <cylinder length="1.219" radius="0.025"/>
      </geometry>
      <material name="black">
        <color rgba="0.1 0.1 0.1 1.0"/>
      </material>
    </visual>
    <collision>
      <geometry>
        <cylinder length="1.219" radius="0.025"/>
      </geometry>
    </collision>
    <inertial>
      <mass value="2.0"/>
      <inertia ixx="0.02" iyy="0.02" izz="0.02"/>
    </inertial>
  </link>
  <joint name="Roller_81_96_joint" type="continuous">
    <parent link="base_link"/>
    <child link="Roller_96"/>
    <origin rpy="1.5707963 0 0" xyz="-9.096375 0 1.15"/>
    <axis xyz="0 0 1"/>
    <dynamics damping="1.0" friction="0.0"/>
  </joint>
  <link name="Roller_98">
    <visual>
      <geometry>
        <cylinder length="1.219" radius="0.025"/>
      </geometry>
      <material name="black">
        <color rgba="0.1 0.1 0.1 1.0"/>
      </material>
    </visual>
    <collision>
      <geometry>
        <cylinder length="1.219" radius="0.025"/>
      </geometry>
    </collision>
    <inertial>
      <mass value="2.0"/>
      <inertia ixx="0.02" iyy="0.02" izz="0.02"/>
    </inertial>
  </link>
  <joint name="Roller_97_98_joint" type="continuous">
    <parent link="base_link"/>
    <child link="Roller_98"/>
    <origin rpy="1.5707963 0 0" xyz="-9.286875 0 1.15"/>
    <axis xyz="0 0 1"/>
    <dynamics damping="1.0" friction="0.0"/>
  </joint>
  <link name="Roller_99">
    <visual>
      <geometry>
        <cylinder length="1.219" radius="0.025"/>
      </geometry>
      <material name="black">
        <color rgba="0.1 0.1 0.1 1.0"/>
      </material>
    </visual>
    <collision>
      <geometry>
        <cylinder length="1.219" radius="0.025"/>
      </geometry>
    </collision>
    <inertial>
      <mass value="2.0"/>
      <inertia ixx="0.02" iyy="0.02" izz="0.02"/>
    </inertial>
  </link>
  <joint name="Roller_97_99_joint" type="continuous">
    <parent link="base_link"/>
    <child link="Roller_99"/>
    <origin rpy="1.5707963 0 0" xyz="-9.382125 0 1.15"/>
    <axis xyz="0 0 1"/>
    <dynamics damping="1.0" friction="0.0"/>
  </joint>
  <link name="Roller_100">
    <visual>
      <geometry>
        <cylinder length="1.219" radius="0.025"/>
      </geometry>
      <material name="black">
        <color rgba="0.1 0.1 0.1 1.0"/>
      </material>
    </visual>
    <collision>
      <geometry>
        <cylinder length="1.219" radius="0.025"/>
      </geometry>
    </collision>
    <inertial>
      <mass value="2.0"/>
      <inertia ixx="0.02" iyy="0.02" izz="0.02"/>
    </inertial>
  </link>
  <joint name="Roller_97_100_joint" type="continuous">
    <parent link="base_link"/>
    <child link="Roller_100"/>
    <origin rpy="1.5707963 0 0" xyz="-9.477375 0 1.15"/>
    <axis xyz="0 0 1"/>
    <dynamics damping="1.0" friction="0.0"/>
  </joint>
  <link name="Roller_101">
    <visual>
      <geometry>
        <cylinder length="1.219" radius="0.025"/>
      </geometry>
      <material name="black">
        <color rgba="0.1 0.1 0.1 1.0"/>
      </material>
    </visual>
    <collision>
      <geometry>
        <cylinder length="1.219" radius="0.025"/>
      </geometry>
    </collision>
    <inertial>
      <mass value="2.0"/>
      <inertia ixx="0.02" iyy="0.02" izz="0.02"/>
    </inertial>
  </link>
  <joint name="Roller_97_101_joint" type="continuous">
    <parent link="base_link"/>
    <child link="Roller_101"/>
    <origin rpy="1.5707963 0 0" xyz="-9.572625 0 1.15"/>
    <axis xyz="0 0 1"/>
    <dynamics damping="1.0" friction="0.0"/>
  </joint>
  <link name="Roller_102">
    <visual>
      <geometry>
        <cylinder length="1.219" radius="0.025"/>
      </geometry>
      <material name="black">
        <color rgba="0.1 0.1 0.1 1.0"/>
      </material>
    </visual>
    <collision>
      <geometry>
        <cylinder length="1.219" radius="0.025"/>
      </geometry>
    </collision>
    <inertial>
      <mass value="2.0"/>
      <inertia ixx="0.02" iyy="0.02" izz="0.02"/>
    </inertial>
  </link>
  <joint name="Roller_97_102_joint" type="continuous">
    <parent link="base_link"/>
    <child link="Roller_102"/>
    <origin rpy="1.5707963 0 0" xyz="-9.667875 0 1.15"/>
    <axis xyz="0 0 1"/>
    <dynamics damping="1.0" friction="0.0"/>
  </joint>
  <link name="Roller_103">
    <visual>
      <geometry>
        <cylinder length="1.219" radius="0.025"/>
      </geometry>
      <material name="black">
        <color rgba="0.1 0.1 0.1 1.0"/>
      </material>
    </visual>
    <collision>
      <geometry>
        <cylinder length="1.219" radius="0.025"/>
      </geometry>
    </collision>
    <inertial>
      <mass value="2.0"/>
      <inertia ixx="0.02" iyy="0.02" izz="0.02"/>
    </inertial>
  </link>
  <joint name="Roller_97_103_joint" type="continuous">
    <parent link="base_link"/>
    <child link="Roller_103"/>
    <origin rpy="1.5707963 0 0" xyz="-9.763125 0 1.15"/>
    <axis xyz="0 0 1"/>
    <dynamics damping="1.0" friction="0.0"/>
  </joint>
  <link name="Roller_104">
    <visual>
      <geometry>
        <cylinder length="1.219" radius="0.025"/>
      </geometry>
      <material name="black">
        <color rgba="0.1 0.1 0.1 1.0"/>
      </material>
    </visual>
    <collision>
      <geometry>
        <cylinder length="1.219" radius="0.025"/>
      </geometry>
    </collision>
    <inertial>
      <mass value="2.0"/>
      <inertia ixx="0.02" iyy="0.02" izz="0.02"/>
    </inertial>
  </link>
  <joint name="Roller_97_104_joint" type="continuous">
    <parent link="base_link"/>
    <child link="Roller_104"/>
    <origin rpy="1.5707963 0 0" xyz="-9.858375 0 1.15"/>
    <axis xyz="0 0 1"/>
    <dynamics damping="1.0" friction="0.0"/>
  </joint>
  <link name="Roller_105">
    <visual>
      <geometry>
        <cylinder length="1.219" radius="0.025"/>
      </geometry>
      <material name="black">
        <color rgba="0.1 0.1 0.1 1.0"/>
      </material>
    </visual>
    <collision>
      <geometry>
        <cylinder length="1.219" radius="0.025"/>
      </geometry>
    </collision>
    <inertial>
      <mass value="2.0"/>
      <inertia ixx="0.02" iyy="0.02" izz="0.02"/>
    </inertial>
  </link>
  <joint name="Roller_97_105_joint" type="continuous">
    <parent link="base_link"/>
    <child link="Roller_105"/>
    <origin rpy="1.5707963 0 0" xyz="-9.953625 0 1.15"/>
    <axis xyz="0 0 1"/>
    <dynamics damping="1.0" friction="0.0"/>
  </joint>
  <link name="Roller_106">
    <visual>
      <geometry>
        <cylinder length="1.219" radius="0.025"/>
      </geometry>
      <material name="black">
        <color rgba="0.1 0.1 0.1 1.0"/>
      </material>
    </visual>
    <collision>
      <geometry>
        <cylinder length="1.219" radius="0.025"/>
      </geometry>
    </collision>
    <inertial>
      <mass value="2.0"/>
      <inertia ixx="0.02" iyy="0.02" izz="0.02"/>
    </inertial>
  </link>
  <joint name="Roller_97_106_joint" type="continuous">
    <parent link="base_link"/>
    <child link="Roller_106"/>
    <origin rpy="1.5707963 0 0" xyz="-10.048875 0 1.15"/>
    <axis xyz="0 0 1"/>
    <dynamics damping="1.0" friction="0.0"/>
  </joint>
  <link name="Roller_107">
    <visual>
      <geometry>
        <cylinder length="1.219" radius="0.025"/>
      </geometry>
      <material name="black">
        <color rgba="0.1 0.1 0.1 1.0"/>
      </material>
    </visual>
    <collision>
      <geometry>
        <cylinder length="1.219" radius="0.025"/>
      </geometry>
    </collision>
    <inertial>
      <mass value="2.0"/>
      <inertia ixx="0.02" iyy="0.02" izz="0.02"/>
    </inertial>
  </link>
  <joint name="Roller_97_107_joint" type="continuous">
    <parent link="base_link"/>
    <child link="Roller_107"/>
    <origin rpy="1.5707963 0 0" xyz="-10.144125 0 1.15"/>
    <axis xyz="0 0 1"/>
    <dynamics damping="1.0" friction="0.0"/>
  </joint>
  <link name="Roller_108">
    <visual>
      <geometry>
        <cylinder length="1.219" radius="0.025"/>
      </geometry>
      <material name="black">
        <color rgba="0.1 0.1 0.1 1.0"/>
      </material>
    </visual>
    <collision>
      <geometry>
        <cylinder length="1.219" radius="0.025"/>
      </geometry>
    </collision>
    <inertial>
      <mass value="2.0"/>
      <inertia ixx="0.02" iyy="0.02" izz="0.02"/>
    </inertial>
  </link>
  <joint name="Roller_97_108_joint" type="continuous">
    <parent link="base_link"/>
    <child link="Roller_108"/>
    <origin rpy="1.5707963 0 0" xyz="-10.239375 0 1.15"/>
    <axis xyz="0 0 1"/>
    <dynamics damping="1.0" friction="0.0"/>
  </joint>
  <link name="Roller_109">
    <visual>
      <geometry>
        <cylinder length="1.219" radius="0.025"/>
      </geometry>
      <material name="black">
        <color rgba="0.1 0.1 0.1 1.0"/>
      </material>
    </visual>
    <collision>
      <geometry>
        <cylinder length="1.219" radius="0.025"/>
      </geometry>
    </collision>
    <inertial>
      <mass value="2.0"/>
      <inertia ixx="0.02" iyy="0.02" izz="0.02"/>
    </inertial>
  </link>
  <joint name="Roller_97_109_joint" type="continuous">
    <parent link="base_link"/>
    <child link="Roller_109"/>
    <origin rpy="1.5707963 0 0" xyz="-10.334625 0 1.15"/>
    <axis xyz="0 0 1"/>
    <dynamics damping="1.0" friction="0.0"/>
  </joint>
  <link name="Roller_110">
    <visual>
      <geometry>
        <cylinder length="1.219" radius="0.025"/>
      </geometry>
      <material name="black">
        <color rgba="0.1 0.1 0.1 1.0"/>
      </material>
    </visual>
    <collision>
      <geometry>
        <cylinder length="1.219" radius="0.025"/>
      </geometry>
    </collision>
    <inertial>
      <mass value="2.0"/>
      <inertia ixx="0.02" iyy="0.02" izz="0.02"/>
    </inertial>
  </link>
  <joint name="Roller_97_110_joint" type="continuous">
    <parent link="base_link"/>
    <child link="Roller_110"/>
    <origin rpy="1.5707963 0 0" xyz="-10.429875000000001 0 1.15"/>
    <axis xyz="0 0 1"/>
    <dynamics damping="1.0" friction="0.0"/>
  </joint>
  <link name="Roller_111">
    <visual>
      <geometry>
        <cylinder length="1.219" radius="0.025"/>
      </geometry>
      <material name="black">
        <color rgba="0.1 0.1 0.1 1.0"/>
      </material>
    </visual>
    <collision>
      <geometry>
        <cylinder length="1.219" radius="0.025"/>
      </geometry>
    </collision>
    <inertial>
      <mass value="2.0"/>
      <inertia ixx="0.02" iyy="0.02" izz="0.02"/>
    </inertial>
  </link>
  <joint name="Roller_97_111_joint" type="continuous">
    <parent link="base_link"/>
    <child link="Roller_111"/>
    <origin rpy="1.5707963 0 0" xyz="-10.525125000000001 0 1.15"/>
    <axis xyz="0 0 1"/>
    <dynamics damping="1.0" friction="0.0"/>
  </joint>
  <link name="Roller_112">
    <visual>
      <geometry>
        <cylinder length="1.219" radius="0.025"/>
      </geometry>
      <material name="black">
        <color rgba="0.1 0.1 0.1 1.0"/>
      </material>
    </visual>
    <collision>
      <geometry>
        <cylinder length="1.219" radius="0.025"/>
      </geometry>
    </collision>
    <inertial>
      <mass value="2.0"/>
      <inertia ixx="0.02" iyy="0.02" izz="0.02"/>
    </inertial>
  </link>
  <joint name="Roller_97_112_joint" type="continuous">
    <parent link="base_link"/>
    <child link="Roller_112"/>
    <origin rpy="1.5707963 0 0" xyz="-10.620375000000001 0 1.15"/>
    <axis xyz="0 0 1"/>
    <dynamics damping="1.0" friction="0.0"/>
  </joint>
  <link name="Roller_114">
    <visual>
      <geometry>
        <cylinder length="1.219" radius="0.025"/>
      </geometry>
      <material name="black">
        <color rgba="0.1 0.1 0.1 1.0"/>
      </material>
    </visual>
    <collision>
      <geometry>
        <cylinder length="1.219" radius="0.025"/>
      </geometry>
    </collision>
    <inertial>
      <mass value="2.0"/>
      <inertia ixx="0.02" iyy="0.02" izz="0.02"/>
    </inertial>
  </link>
  <joint name="Roller_113_114_joint" type="continuous">
    <parent link="base_link"/>
    <child link="Roller_114"/>
    <origin rpy="1.5707963 0 0" xyz="-10.810875 0 1.15"/>
    <axis xyz="0 0 1"/>
    <dynamics damping="1.0" friction="0.0"/>
  </joint>
  <link name="Roller_115">
    <visual>
      <geometry>
        <cylinder length="1.219" radius="0.025"/>
      </geometry>
      <material name="black">
        <color rgba="0.1 0.1 0.1 1.0"/>
      </material>
    </visual>
    <collision>
      <geometry>
        <cylinder length="1.219" radius="0.025"/>
      </geometry>
    </collision>
    <inertial>
      <mass value="2.0"/>
      <inertia ixx="0.02" iyy="0.02" izz="0.02"/>
    </inertial>
  </link>
  <joint name="Roller_113_115_joint" type="continuous">
    <parent link="base_link"/>
    <child link="Roller_115"/>
    <origin rpy="1.5707963 0 0" xyz="-10.906125 0 1.15"/>
    <axis xyz="0 0 1"/>
    <dynamics damping="1.0" friction="0.0"/>
  </joint>
  <link name="Roller_116">
    <visual>
      <geometry>
        <cylinder length="1.219" radius="0.025"/>
      </geometry>
      <material name="black">
        <color rgba="0.1 0.1 0.1 1.0"/>
      </material>
    </visual>
    <collision>
      <geometry>
        <cylinder length="1.219" radius="0.025"/>
      </geometry>
    </collision>
    <inertial>
      <mass value="2.0"/>
      <inertia ixx="0.02" iyy="0.02" izz="0.02"/>
    </inertial>
  </link>
  <joint name="Roller_113_116_joint" type="continuous">
    <parent link="base_link"/>
    <child link="Roller_116"/>
    <origin rpy="1.5707963 0 0" xyz="-11.001375 0 1.15"/>
    <axis xyz="0 0 1"/>
    <dynamics damping="1.0" friction="0.0"/>
  </joint>
  <link name="Roller_117">
    <visual>
      <geometry>
        <cylinder length="1.219" radius="0.025"/>
      </geometry>
      <material name="black">
        <color rgba="0.1 0.1 0.1 1.0"/>
      </material>
    </visual>
    <collision>
      <geometry>
        <cylinder length="1.219" radius="0.025"/>
      </geometry>
    </collision>
    <inertial>
      <mass value="2.0"/>
      <inertia ixx="0.02" iyy="0.02" izz="0.02"/>
    </inertial>
  </link>
  <joint name="Roller_113_117_joint" type="continuous">
    <parent link="base_link"/>
    <child link="Roller_117"/>
    <origin rpy="1.5707963 0 0" xyz="-11.096625 0 1.15"/>
    <axis xyz="0 0 1"/>
    <dynamics damping="1.0" friction="0.0"/>
  </joint>
  <link name="Roller_118">
    <visual>
      <geometry>
        <cylinder length="1.219" radius="0.025"/>
      </geometry>
      <material name="black">
        <color rgba="0.1 0.1 0.1 1.0"/>
      </material>
    </visual>
    <collision>
      <geometry>
        <cylinder length="1.219" radius="0.025"/>
      </geometry>
    </collision>
    <inertial>
      <mass value="2.0"/>
      <inertia ixx="0.02" iyy="0.02" izz="0.02"/>
    </inertial>
  </link>
  <joint name="Roller_113_118_joint" type="continuous">
    <parent link="base_link"/>
    <child link="Roller_118"/>
    <origin rpy="1.5707963 0 0" xyz="-11.191875 0 1.15"/>
    <axis xyz="0 0 1"/>
    <dynamics damping="1.0" friction="0.0"/>
  </joint>
  <link name="Roller_119">
    <visual>
      <geometry>
        <cylinder length="1.219" radius="0.025"/>
      </geometry>
      <material name="black">
        <color rgba="0.1 0.1 0.1 1.0"/>
      </material>
    </visual>
    <collision>
      <geometry>
        <cylinder length="1.219" radius="0.025"/>
      </geometry>
    </collision>
    <inertial>
      <mass value="2.0"/>
      <inertia ixx="0.02" iyy="0.02" izz="0.02"/>
    </inertial>
  </link>
  <joint name="Roller_113_119_joint" type="continuous">
    <parent link="base_link"/>
    <child link="Roller_119"/>
    <origin rpy="1.5707963 0 0" xyz="-11.287125 0 1.15"/>
    <axis xyz="0 0 1"/>
    <dynamics damping="1.0" friction="0.0"/>
  </joint>
  <link name="Roller_120">
    <visual>
      <geometry>
        <cylinder length="1.219" radius="0.025"/>
      </geometry>
      <material name="black">
        <color rgba="0.1 0.1 0.1 1.0"/>
      </material>
    </visual>
    <collision>
      <geometry>
        <cylinder length="1.219" radius="0.025"/>
      </geometry>
    </collision>
    <inertial>
      <mass value="2.0"/>
      <inertia ixx="0.02" iyy="0.02" izz="0.02"/>
    </inertial>
  </link>
  <joint name="Roller_113_120_joint" type="continuous">
    <parent link="base_link"/>
    <child link="Roller_120"/>
    <origin rpy="1.5707963 0 0" xyz="-11.382375 0 1.15"/>
    <axis xyz="0 0 1"/>
    <dynamics damping="1.0" friction="0.0"/>
  </joint>
  <link name="Roller_121">
    <visual>
      <geometry>
        <cylinder length="1.219" radius="0.025"/>
      </geometry>
      <material name="black">
        <color rgba="0.1 0.1 0.1 1.0"/>
      </material>
    </visual>
    <collision>
      <geometry>
        <cylinder length="1.219" radius="0.025"/>
      </geometry>
    </collision>
    <inertial>
      <mass value="2.0"/>
      <inertia ixx="0.02" iyy="0.02" izz="0.02"/>
    </inertial>
  </link>
  <joint name="Roller_113_121_joint" type="continuous">
    <parent link="base_link"/>
    <child link="Roller_121"/>
    <origin rpy="1.5707963 0 0" xyz="-11.477625 0 1.15"/>
    <axis xyz="0 0 1"/>
    <dynamics damping="1.0" friction="0.0"/>
  </joint>
  <link name="Roller_122">
    <visual>
      <geometry>
        <cylinder length="1.219" radius="0.025"/>
      </geometry>
      <material name="black">
        <color rgba="0.1 0.1 0.1 1.0"/>
      </material>
    </visual>
    <collision>
      <geometry>
        <cylinder length="1.219" radius="0.025"/>
      </geometry>
    </collision>
    <inertial>
      <mass value="2.0"/>
      <inertia ixx="0.02" iyy="0.02" izz="0.02"/>
    </inertial>
  </link>
  <joint name="Roller_113_122_joint" type="continuous">
    <parent link="base_link"/>
    <child link="Roller_122"/>
    <origin rpy="1.5707963 0 0" xyz="-11.572875 0 1.15"/>
    <axis xyz="0 0 1"/>
    <dynamics damping="1.0" friction="0.0"/>
  </joint>
  <link name="Roller_123">
    <visual>
      <geometry>
        <cylinder length="1.219" radius="0.025"/>
      </geometry>
      <material name="black">
        <color rgba="0.1 0.1 0.1 1.0"/>
      </material>
    </visual>
    <collision>
      <geometry>
        <cylinder length="1.219" radius="0.025"/>
      </geometry>
    </collision>
    <inertial>
      <mass value="2.0"/>
      <inertia ixx="0.02" iyy="0.02" izz="0.02"/>
    </inertial>
  </link>
  <joint name="Roller_113_123_joint" type="continuous">
    <parent link="base_link"/>
    <child link="Roller_123"/>
    <origin rpy="1.5707963 0 0" xyz="-11.668125 0 1.15"/>
    <axis xyz="0 0 1"/>
    <dynamics damping="1.0" friction="0.0"/>
  </joint>
  <link name="Roller_124">
    <visual>
      <geometry>
        <cylinder length="1.219" radius="0.025"/>
      </geometry>
      <material name="black">
        <color rgba="0.1 0.1 0.1 1.0"/>
      </material>
    </visual>
    <collision>
      <geometry>
        <cylinder length="1.219" radius="0.025"/>
      </geometry>
    </collision>
    <inertial>
      <mass value="2.0"/>
      <inertia ixx="0.02" iyy="0.02" izz="0.02"/>
    </inertial>
  </link>
  <joint name="Roller_113_124_joint" type="continuous">
    <parent link="base_link"/>
    <child link="Roller_124"/>
    <origin rpy="1.5707963 0 0" xyz="-11.763375 0 1.15"/>
    <axis xyz="0 0 1"/>
    <dynamics damping="1.0" friction="0.0"/>
  </joint>
  <link name="Roller_125">
    <visual>
      <geometry>
        <cylinder length="1.219" radius="0.025"/>
      </geometry>
      <material name="black">
        <color rgba="0.1 0.1 0.1 1.0"/>
      </material>
    </visual>
    <collision>
      <geometry>
        <cylinder length="1.219" radius="0.025"/>
      </geometry>
    </collision>
    <inertial>
      <mass value="2.0"/>
      <inertia ixx="0.02" iyy="0.02" izz="0.02"/>
    </inertial>
  </link>
  <joint name="Roller_113_125_joint" type="continuous">
    <parent link="base_link"/>
    <child link="Roller_125"/>
    <origin rpy="1.5707963 0 0" xyz="-11.858625 0 1.15"/>
    <axis xyz="0 0 1"/>
    <dynamics damping="1.0" friction="0.0"/>
  </joint>
  <link name="Roller_126">
    <visual>
      <geometry>
        <cylinder length="1.219" radius="0.025"/>
      </geometry>
      <material name="black">
        <color rgba="0.1 0.1 0.1 1.0"/>
      </material>
    </visual>
    <collision>
      <geometry>
        <cylinder length="1.219" radius="0.025"/>
      </geometry>
    </collision>
    <inertial>
      <mass value="2.0"/>
      <inertia ixx="0.02" iyy="0.02" izz="0.02"/>
    </inertial>
  </link>
  <joint name="Roller_113_126_joint" type="continuous">
    <parent link="base_link"/>
    <child link="Roller_126"/>
    <origin rpy="1.5707963 0 0" xyz="-11.953875 0 1.15"/>
    <axis xyz="0 0 1"/>
    <dynamics damping="1.0" friction="0.0"/>
  </joint>
  <link name="Roller_127">
    <visual>
      <geometry>
        <cylinder length="1.219" radius="0.025"/>
      </geometry>
      <material name="black">
        <color rgba="0.1 0.1 0.1 1.0"/>
      </material>
    </visual>
    <collision>
      <geometry>
        <cylinder length="1.219" radius="0.025"/>
      </geometry>
    </collision>
    <inertial>
      <mass value="2.0"/>
      <inertia ixx="0.02" iyy="0.02" izz="0.02"/>
    </inertial>
  </link>
  <joint name="Roller_113_127_joint" type="continuous">
    <parent link="base_link"/>
    <child link="Roller_127"/>
    <origin rpy="1.5707963 0 0" xyz="-12.049125 0 1.15"/>
    <axis xyz="0 0 1"/>
    <dynamics damping="1.0" friction="0.0"/>
  </joint>
  <link name="Roller_128">
    <visual>
      <geometry>
        <cylinder length="1.219" radius="0.025"/>
      </geometry>
      <material name="black">
        <color rgba="0.1 0.1 0.1 1.0"/>
      </material>
    </visual>
    <collision>
      <geometry>
        <cylinder length="1.219" radius="0.025"/>
      </geometry>
    </collision>
    <inertial>
      <mass value="2.0"/>
      <inertia ixx="0.02" iyy="0.02" izz="0.02"/>
    </inertial>
  </link>
  <joint name="Roller_113_128_joint" type="continuous">
    <parent link="base_link"/>
    <child link="Roller_128"/>
    <origin rpy="1.5707963 0 0" xyz="-12.144375 0 1.15"/>
    <axis xyz="0 0 1"/>
    <dynamics damping="1.0" friction="0.0"/>
  </joint>
</robot>
